<!doctype html>
<html class="no-js" lang="en">

<head>
  <!-- Global site tag (gtag.js) - Google Analytics -->
  <script async src="https://www.googletagmanager.com/gtag/js?id=UA-134228602-6"></script>
  <script>
    window.dataLayer = window.dataLayer || [];
    function gtag(){dataLayer.push(arguments);}
    gtag('js', new Date());

    gtag('config', 'UA-134228602-6');
  </script>

  <meta charset="utf-8">
  <meta http-equiv="x-ua-compatible" content="ie=edge">
  <title>üë®üèΩ‚ÄçüöÄ ü•Ä ü§òüèæ Verheerende Ausnahmen üíâ üçï üë®üèΩ‚Äçüî¨</title>
  <link rel="icon" type="image/x-icon" href="/favicon.ico" />
  <meta name="description" content="Noch einmal dar√ºber, warum es schlecht ist, Ausnahmen in Destruktoren zu werfen 


 Viele C ++ - Experten (z. B. Herb Sutter ) lehren uns, dass das Au...">
  <meta name="viewport" content="width=device-width, initial-scale=1, shrink-to-fit=no">

  <link rel="stylesheet" href="../../css/main.css">

  <link href="https://fonts.googleapis.com/css?family=Quicksand&display=swap" rel="stylesheet">

  <script src="https://cdnjs.cloudflare.com/ajax/libs/jquery/3.3.1/jquery.min.js"></script>
  <script>window.jQuery || document.write('<script src="../../js/vendors/jquery-3.3.1.min.js"><\/script>')</script>

  <script>document.write('<script src="//pagea' + 'd2.googles' + 'yndication.com/pagea' + 'd/js/a' + 'dsby' + 'google.js"><\/script>')</script>
  <script>
        var superSpecialObject = {};
        superSpecialObject['google_a' + 'd_client'] = 'ca-p' + 'ub-6974184241884155';
        superSpecialObject['enable_page_level_a' + 'ds'] = true;
       (window['a' + 'dsbygoogle'] = window['a' + 'dsbygoogle'] || []).push(superSpecialObject);
  </script>
</head>

<body>
  <!--[if lte IE 9]>
    <p class="browserupgrade">You are using an <strong>outdated</strong> browser. Please <a href="https://browsehappy.com/">upgrade your browser</a> to improve your experience and security.</p>
  <![endif]-->
  <header class="page-header js-page-header">
    <a class="page-header-logo-container" href="https://weekly-geekly-es.github.io/index.html"></a>
    <div class="page-header-text">Geekly articles weekly</div>
  </header>
  <section class="page js-page"><h1>Verheerende Ausnahmen</h1><div class="post__body post__body_full"><div class="post__text post__text-html post__text_v1" id="post-content-body" data-io-article-url="https://habr.com/ru/post/433944/"><h2 id="eschyo-raz-o-tom-pochemu-ploho-brosat-isklyucheniya-v-destruktorah">  Noch einmal dar√ºber, warum es schlecht ist, Ausnahmen in Destruktoren zu werfen </h2><br><p>  Viele C ++ - Experten (z. B. <a href="https://translate.googleusercontent.com/translate_c?depth=1&amp;rurl=translate.google.com&amp;sl=ru&amp;sp=nmt4&amp;tl=de&amp;u=">Herb Sutter</a> ) lehren uns, dass das Ausl√∂sen von Ausnahmen in Destruktoren schlecht ist, da Sie w√§hrend der Stack-Promotion in den Destruktor gelangen k√∂nnen, wenn bereits eine Ausnahme ausgel√∂st wird. Wenn in diesem Moment eine andere Ausnahme ausgel√∂st wird, wird <em>std</em> als Ergebnis aufgerufen <em>:: terminate ()</em> .  Der C ++ 17-Sprachstandard (im Folgenden verweise ich auf die frei verf√ºgbare Version des Entwurfs <a href="https://translate.googleusercontent.com/translate_c?depth=1&amp;rurl=translate.google.com&amp;sl=ru&amp;sp=nmt4&amp;tl=de&amp;u=">N4713</a> ) zu diesem Thema sagt uns Folgendes: </p><a name="habracut"></a><br><blockquote>  <strong>18.5.1 Die Funktion std :: terminate () [au√üer.terminate]</strong> <br><br>  1 In einigen Situationen muss die Ausnahmebehandlung f√ºr weniger subtile Fehlerbehandlungstechniken abgebrochen werden.  [Anmerkung: <br><br>  Diese Situationen sind: <br><br>  ... <br><br>  (1.4) wenn die Zerst√∂rung eines Objekts w√§hrend des Abwickelns des Stapels (18.2) durch Ausl√∂sen einer Ausnahme endet, oder <br><br>  ... <br><br>  - Endnote] </blockquote><p>  Schauen wir uns ein einfaches Beispiel an: </p><br><pre><code class="plaintext hljs">#include &lt;iostream&gt; class PrintInDestructor { public: ~PrintInDestructor() noexcept { std::cerr &lt;&lt; "~PrintInDestructor() invoked\n"; } }; void throw_int_func() { std::cerr &lt;&lt; "throw_int_func() invoked\n"; throw 1; } class ThrowInDestructor { public: ~ThrowInDestructor() noexcept(false) { std::cerr &lt;&lt; "~ThrowInDestructor() invoked\n"; throw_int_func(); } private: PrintInDestructor member_; }; int main(int, char**) { try { ThrowInDestructor bad; throw "BANG!"; } catch (int i) { std::cerr &lt;&lt; "Catched int exception: " &lt;&lt; i &lt;&lt; "\n"; } catch (const char* c) { std::cerr &lt;&lt; "Catched const char* exception: " &lt;&lt; c &lt;&lt; "\n"; } catch (...) { std::cerr &lt;&lt; "Catched unknown exception\n"; } return 0; }</code> </pre> <br><p>  Ergebnis: </p><br><pre> <code class="plaintext hljs">~ThrowInDestructor() invoked throw_int_func() invoked ~PrintInDestructor() invoked terminate called after throwing an instance of 'int' Aborted</code> </pre> <br><p>  Beachten Sie, dass der <em>PrintInDestructor-</em> Destruktor weiterhin aufgerufen wird, d. H.  Nach dem Ausl√∂sen der zweiten Ausnahme wird die Stapelheraufstufung nicht unterbrochen.  Der Standard (derselbe Absatz 18.5.1) zu diesem Thema lautet wie folgt: </p><br><blockquote>  2 ... In der Situation, in der kein passender Handler gefunden wird, <br>  Es ist implementierungsdefiniert, ob der Stack abgewickelt wird, bevor std :: terminate () aufgerufen wird.  In <br>  die Situation, in der die Suche nach einem Handler (18.3) auf den √§u√üersten Block einer Funktion mit a trifft <br>  Nicht ausl√∂sende Ausnahmespezifikation (18.4), es ist implementierungsdefiniert, ob der Stapel abgewickelt wird. <br>  teilweise oder gar nicht abgewickelt, bevor std :: terminate () aufgerufen wird ... </blockquote><p>  Ich habe dieses Beispiel an mehreren Versionen von <strong>GCC</strong> (8.2, 7.3) und <strong>Clang</strong> (6.0, 5.0) getestet, √ºberall dort, wo die F√∂rderung des Stacks fortgesetzt wird.  Wenn Sie auf einen Compiler sto√üen, bei dem die Implementierung anders definiert ist, schreiben Sie dies bitte in den Kommentaren. </p><br><p>  Es sollte auch beachtet werden, dass <em>std :: terminate ()</em> nur dann aufgerufen wird, wenn der Stapel abgewickelt wird, wenn eine Ausnahme aus dem Destruktor ausgel√∂st wird.  Wenn sich im Destruktor ein Try / Catch-Block befindet, der die Ausnahme abf√§ngt und nicht weiter ausl√∂st, wird die Heraufstufung des Stapels der externen Ausnahme nicht unterbrochen. </p><br><pre> <code class="plaintext hljs">class ThrowCatchInDestructor { public: ~ThrowCatchInDestructor() noexcept(false) { try { throw_int_func(); } catch (int i) { std::cerr &lt;&lt; "Catched int in ~ThrowCatchInDestructor(): " &lt;&lt; i &lt;&lt; "\n"; } } private: PrintInDestructor member_; }; int main(int, char**) { try { ThrowCatchInDestructor good; std::cerr &lt;&lt; "ThrowCatchInDestructor instance created\n"; throw "BANG!"; } catch (int i) { std::cerr &lt;&lt; "Catched int exception: " &lt;&lt; i &lt;&lt; "\n"; } catch (const char* s) { std::cerr &lt;&lt; "Catched const char* exception: " &lt;&lt; s &lt;&lt; "\n"; } catch (...) { std::cerr &lt;&lt; "Catched unknown exception\n"; } return 0; }</code> </pre> <br><p>  Anzeigen </p><br><pre> <code class="plaintext hljs">ThrowCatchInDestructor instance created throw_int_func() invoked Catched int in ~ThrowCatchInDestructor(): 1 ~PrintInDestructor() invoked Catched const char* exception: BANG!</code> </pre> <br><p>  Wie vermeide ich unangenehme Situationen?  Theoretisch ist alles einfach: Wirf niemals Ausnahmen in den Destruktor.  In der Praxis ist es jedoch nicht so einfach, diese einfache Anforderung sch√∂n und elegant zu verwirklichen. </p><br><h2 id="esli-nelzya-no-ochen-hochetsya">  Wenn Sie nicht k√∂nnen, aber wirklich wollen ... </h2><br><blockquote>  Ich werde sofort bemerken, dass ich nicht versuche, Ausnahmen vom Destruktor zu rechtfertigen, und nach Sutter, Meyers und anderen C ++ - Gurus fordere ich Sie <strong>auf, dies</strong> niemals zu <strong>versuchen</strong> (zumindest im neuen Code).  In der Praxis kann ein Programmierer jedoch m√∂glicherweise auf Legacy-Code sto√üen, der nicht so einfach zu hohen Standards f√ºhrt.  Dar√ºber hinaus k√∂nnen die nachfolgend h√§ufig beschriebenen Techniken w√§hrend des Debugging-Prozesses n√ºtzlich sein. </blockquote><p>  Zum Beispiel entwickeln wir eine Bibliothek mit einer Wrapper-Klasse, die die Arbeit mit einer bestimmten Ressource kapselt.  In √úbereinstimmung mit den Prinzipien von RAII greifen wir auf die Ressource im Konstruktor zu und m√ºssen sie im Destruktor freigeben.  Was aber, wenn ein Versuch, eine Ressource freizugeben, fehlschl√§gt?  Optionen zur L√∂sung dieses Problems: </p><br><ul><li>  Ignorieren Sie den Fehler.  Schlecht, weil wir ein Problem verbergen, das andere Teile des Systems betreffen k√∂nnte. </li><li>  Schreiben Sie in das Protokoll.  Besser als es einfach zu ignorieren, aber immer noch schlecht, weil  Unsere Bibliothek wei√ü nichts √ºber die Protokollierungsrichtlinien, die in dem System angewendet werden, das sie verwendet.  Das Standardprotokoll kann nach / dev / null umgeleitet werden, wodurch wiederum kein Fehler angezeigt wird. </li><li>  Nehmen Sie die Freigabe der Ressource in eine separate Funktion, die einen Wert zur√ºckgibt oder eine Ausnahme ausl√∂st, und zwingen Sie den Klassenbenutzer, ihn selbst aufzurufen.  Es ist schlecht, weil der Benutzer dies √ºberhaupt vergessen kann und wir ein Ressourcenleck erhalten. </li><li>  Eine Ausnahme ausl√∂sen.  Gut in gew√∂hnlichen F√§llen, wie  Der Klassenbenutzer kann die Ausnahme abfangen und auf standardm√§√üige Weise Informationen √ºber den Fehler abrufen.  Schlecht w√§hrend der Stapelwerbung, da  f√ºhrt zu <em>std :: terminate ()</em> . </li></ul><br><p>  Wie kann man verstehen, ob wir gerade dabei sind, den Stack ausnahmsweise zu bewerben oder nicht?  In C ++ gibt es daf√ºr eine spezielle Funktion <em>std :: uncaught_exception ()</em> .  Mit seiner Hilfe k√∂nnen wir in einer normalen Situation sicher eine Ausnahme ausl√∂sen oder etwas weniger Richtiges tun, was jedoch nicht dazu f√ºhrt, dass w√§hrend der Stapel-Promotion eine Ausnahme ausgel√∂st wird. </p><br><pre> <code class="plaintext hljs">class ThrowInDestructor { public: ~ThrowInDestructor() noexcept(false) { if (std::uncaught_exception()) { std::cerr &lt;&lt; "~ThrowInDestructor() stack unwinding, not throwing\n"; } else { std::cerr &lt;&lt; "~ThrowInDestructor() normal case, throwing\n"; throw_int_func(); } } private: PrintInDestructor member_; }; int main(int, char**) { try { ThrowInDestructor normal; std::cerr &lt;&lt; "ThrowInDestructor normal destruction\n"; } catch (int i) { std::cerr &lt;&lt; "Catched int exception: " &lt;&lt; i &lt;&lt; "\n"; } try { ThrowInDestructor stack_unwind; std::cerr &lt;&lt; "ThrowInDestructor stack unwinding\n"; throw "BANG!"; } catch (int i) { std::cerr &lt;&lt; "Catched int exception: " &lt;&lt; i &lt;&lt; "\n"; } catch (const char* s) { std::cerr &lt;&lt; "Catched const char* exception: " &lt;&lt; s &lt;&lt; "\n"; } catch (...) { std::cerr &lt;&lt; "Catched unknown exception\n"; } return 0; }</code> </pre> <br><p>  Ergebnis: </p><br><pre> <code class="plaintext hljs">ThrowInDestructor normal destruction ~ThrowInDestructor() normal case, throwing throw_int_func() invoked ~PrintInDestructor() invoked Catched int exception: 1 ThrowInDestructor stack unwinding ~ThrowInDestructor() stack unwinding, not throwing ~PrintInDestructor() invoked Catched const char* exception: BANG!</code> </pre> <br><p>  Beachten Sie, dass die Funktion <em>std :: uncaught_exception ()</em> seit C ++ Standard 17 <em>veraltet</em> ist. Um das Beispiel zu kompilieren, muss daher das entsprechende Vorning unterdr√ºckt werden (siehe <a href="https://translate.googleusercontent.com/translate_c?depth=1&amp;rurl=translate.google.com&amp;sl=ru&amp;sp=nmt4&amp;tl=de&amp;u=">Repository mit Beispielen aus dem Artikel</a> ). </p><br><p>  Das Problem mit dieser Funktion ist, dass sie pr√ºft, ob wir den Stapel ausnahmsweise drehen.  Es ist jedoch unm√∂glich zu verstehen, ob der aktuelle Destruktor w√§hrend des Prozesses der Stapelheraufstufung aufgerufen wird.  Wenn eine Stapelheraufstufung vorliegt, der Destruktor eines Objekts jedoch normal aufgerufen wird, gibt <em>std :: uncaught_exception ()</em> weiterhin <em>true zur√ºck</em> . </p><br><pre> <code class="plaintext hljs">class MayThrowInDestructor { public: ~MayThrowInDestructor() noexcept(false) { if (std::uncaught_exception()) { std::cerr &lt;&lt; "~MayThrowInDestructor() stack unwinding, not throwing\n"; } else { std::cerr &lt;&lt; "~MayThrowInDestructor() normal case, throwing\n"; throw_int_func(); } } }; class ThrowCatchInDestructor { public: ~ThrowCatchInDestructor() noexcept(false) { try { MayThrowInDestructor may_throw; } catch (int i) { std::cerr &lt;&lt; "Catched int in ~ThrowCatchInDestructor(): " &lt;&lt; i &lt;&lt; "\n"; } } private: PrintInDestructor member_; }; int main(int, char**) { try { ThrowCatchInDestructor stack_unwind; std::cerr &lt;&lt; "ThrowInDestructor stack unwinding\n"; throw "BANG!"; } catch (int i) { std::cerr &lt;&lt; "Catched int exception: " &lt;&lt; i &lt;&lt; "\n"; } catch (const char* s) { std::cerr &lt;&lt; "Catched const char* exception: " &lt;&lt; s &lt;&lt; "\n"; } catch (...) { std::cerr &lt;&lt; "Catched unknown exception\n"; } return 0; }</code> </pre> <br><p>  Ergebnis: </p><br><pre> <code class="plaintext hljs">ThrowInDestructor stack unwinding ~MayThrowInDestructor() stack unwinding, not throwing ~PrintInDestructor() invoked Catched const char* exception: BANG!</code> </pre> <br><p>  Im neuen C ++ 17-Standard wurde die Funktion <em>std :: uncaught_exceptions ()</em> eingef√ºhrt, um <em>std :: uncaught_exception ()</em> zu ersetzen (beachten Sie den Plural), die anstelle eines Booleschen Werts die Anzahl der derzeit aktiven Ausnahmen zur√ºckgibt (hier eine ausf√ºhrliche <a href="https://translate.googleusercontent.com/translate_c?depth=1&amp;rurl=translate.google.com&amp;sl=ru&amp;sp=nmt4&amp;tl=de&amp;u=">Begr√ºndung</a> ). </p><br><p>  So wird das oben beschriebene Problem mit <em>std :: uncaught_exceptions ()</em> gel√∂st: </p><br><pre> <code class="plaintext hljs">class MayThrowInDestructor { public: MayThrowInDestructor() : exceptions_(std::uncaught_exceptions()) {} ~MayThrowInDestructor() noexcept(false) { if (std::uncaught_exceptions() &gt; exceptions_) { std::cerr &lt;&lt; "~MayThrowInDestructor() stack unwinding, not throwing\n"; } else { std::cerr &lt;&lt; "~MayThrowInDestructor() normal case, throwing\n"; throw_int_func(); } } private: int exceptions_; }; class ThrowCatchInDestructor { public: ~ThrowCatchInDestructor() noexcept(false) { try { MayThrowInDestructor may_throw; } catch (int i) { std::cerr &lt;&lt; "Catched int in ~ThrowCatchInDestructor(): " &lt;&lt; i &lt;&lt; "\n"; } } private: PrintInDestructor member_; }; int main(int, char**) { try { ThrowCatchInDestructor stack_unwind; std::cerr &lt;&lt; "ThrowInDestructor stack unwinding\n"; throw "BANG!"; } catch (int i) { std::cerr &lt;&lt; "Catched int exception: " &lt;&lt; i &lt;&lt; "\n"; } catch (const char* s) { std::cerr &lt;&lt; "Catched const char* exception: " &lt;&lt; s &lt;&lt; "\n"; } catch (...) { std::cerr &lt;&lt; "Catched unknown exception\n"; } return 0; }</code> </pre> <br><p>  Ergebnis: </p><br><pre> <code class="plaintext hljs">ThrowInDestructor stack unwinding ~MayThrowInDestructor() normal case, throwing throw_int_func() invoked Catched int in ~ThrowCatchInDestructor(): 1 ~PrintInDestructor() invoked Catched const char* exception: BANG!</code> </pre> <br><h2 id="kogda-ochen-ochen-hochetsya-vybrosit-srazu-neskolko-isklyucheniy">  Wenn ich wirklich, wirklich ein paar Ausnahmen auf einmal werfen m√∂chte </h2><br><p>  <em>std :: uncaught_exceptions ()</em> vermeidet das Aufrufen von <em>std :: terminate ()</em> , hilft jedoch nicht dabei, mehrere Ausnahmen korrekt zu behandeln.  Im Idealfall h√§tte ich gerne einen Mechanismus, mit dem ich alle ausgel√∂sten Ausnahmen speichern und dann an einem Ort verarbeiten kann. </p><br><blockquote>  Ich m√∂chte noch einmal daran erinnern, dass der von mir unten vorgeschlagene Mechanismus nur zur Demonstration des Konzepts dient und nicht f√ºr die Verwendung in echtem Industriecode empfohlen wird. </blockquote><p>  Das Wesentliche der Idee ist, Ausnahmen abzufangen und in einem Container zu speichern und sie dann einzeln abzurufen und zu verarbeiten.  Um Ausnahmeobjekte zu speichern, hat C ++ einen speziellen Typ <em>std :: exception_ptr</em> .  Die Typstruktur im Standard wird nicht offenbart, es wird jedoch gesagt, dass es sich im Wesentlichen um <em>shared_ptr</em> pro Ausnahmeobjekt handelt. </p><br><p>  Wie werden diese Ausnahmen dann verarbeitet?  <em>Hierf√ºr</em> gibt es eine Funktion <em>std :: rethrow_exception ()</em> , die einen Zeiger <em>std :: exception_ptr verwendet</em> und die entsprechende Ausnahme <em>ausl√∂st</em> .  Wir m√ºssen es nur mit dem entsprechenden catch-Abschnitt abfangen und verarbeiten, wonach wir mit dem n√§chsten Ausnahmeobjekt fortfahren k√∂nnen. </p><br><pre> <code class="plaintext hljs">using exceptions_queue = std::stack&lt;std::exception_ptr&gt;; // Get exceptions queue for current thread exceptions_queue&amp; get_queue() { thread_local exceptions_queue queue_; return queue_; } // Invoke functor and save exception in queue void safe_invoke(std::function&lt;void()&gt; f) noexcept { try { f(); } catch (...) { get_queue().push(std::current_exception()); } } class ThrowInDestructor { public: ~ThrowInDestructor() noexcept { std::cerr &lt;&lt; "~ThrowInDestructor() invoked\n"; safe_invoke([]() { throw_int_func(); }); } private: PrintInDestructor member_; }; int main(int, char**) { safe_invoke([]() { ThrowInDestructor bad; throw "BANG!"; }); auto&amp; q = get_queue(); while (!q.empty()) { try { std::exception_ptr ex = q.top(); q.pop(); if (ex != nullptr) { std::rethrow_exception(ex); } } catch (int i) { std::cerr &lt;&lt; "Catched int exception: " &lt;&lt; i &lt;&lt; "\n"; } catch (const char* s) { std::cerr &lt;&lt; "Catched const char* exception: " &lt;&lt; s &lt;&lt; "\n"; } catch (...) { std::cerr &lt;&lt; "Catched unknown exception\n"; } } return 0; }</code> </pre> <br><p>  Ergebnis: </p><br><pre> <code class="plaintext hljs">~ThrowInDestructor() invoked throw_int_func() invoked ~PrintInDestructor() invoked Catched const char* exception: BANG! Catched int exception: 1</code> </pre> <br><p>  Im obigen Beispiel wird der Stapel zum Speichern von Ausnahmeobjekten verwendet. Die Ausnahmebehandlung wird jedoch gem√§√ü dem FIFO-Prinzip durchgef√ºhrt (dh logischerweise ist dies die Warteschlange - die zuerst ausgel√∂ste Ausnahme ist die erste, die verarbeitet wird). </p><br><h2 id="vyvody">  Schlussfolgerungen </h2><br><p>  Das Ausl√∂sen von Ausnahmen in Objektdestruktoren ist wirklich eine schlechte Idee, und in jedem neuen Code empfehle ich dringend, dies nicht zu tun, indem <em>Sie</em> keine <em>Ausnahmedestruktoren</em> deklarieren.  Bei der Unterst√ºtzung und dem Debuggen von Legacy-Code kann es jedoch erforderlich sein, Ausnahmen, die von Destruktoren ausgel√∂st werden, auch w√§hrend der Stack-Heraufstufung, korrekt zu behandeln, und modernes C ++ bietet uns Mechanismen daf√ºr.  Ich hoffe, dass die im Artikel vorgestellten Ideen Ihnen auf diesem schwierigen Weg helfen werden. </p><br><h2 id="ssylki">  Referenzen </h2><br><p>  <a href="https://translate.googleusercontent.com/translate_c?depth=1&amp;rurl=translate.google.com&amp;sl=ru&amp;sp=nmt4&amp;tl=de&amp;u=">Repository mit Beispielen aus dem Artikel</a> </p></div></div><p>Source: <a rel="nofollow" href="https://habr.com/ru/post/de433944/">https://habr.com/ru/post/de433944/</a></p>
<section class="more-articles-navigation-panel js-more-articles-navigation-panel">
<h4>More articles:</h4>
<nav class="list-of-articles-container js-list-of-articles-container"><ul class="list-of-pages js-list-of-pages">
<li><a href="../de433932/index.html">Wir schie√üen in den Fu√ü und verarbeiten die Eingabedaten</a></li>
<li><a href="../de433934/index.html">SAFe oder Scaled Agile Framework</a></li>
<li><a href="../de433936/index.html">Auf der Suche nach einem Hightech-Geschenk f√ºr ein Kind? Denken Sie an einen Spielplatz, nicht an einen Laufstall</a></li>
<li><a href="../de433938/index.html">Wie Yandex und Google das Jahr zusammenfassen</a></li>
<li><a href="../de433940/index.html">Wie viel kostet Review im AppStore?</a></li>
<li><a href="../de433946/index.html">Spickzettel f√ºr k√ºnstliche Intelligenz - werfen Sie den √úberschuss weg, lehren Sie die Hauptsache. Trainingssequenz-Verarbeitungstechnik</a></li>
<li><a href="../de433948/index.html">So machen Sie die Zahlung bequemer: die Erfahrung eines IaaS-Anbieters</a></li>
<li><a href="../de433952/index.html">10 Gr√ºnde, sich f√ºr eine L√∂sung f√ºr SAP HANA von HPE zu entscheiden. Teil 2</a></li>
<li><a href="../de433954/index.html">Acht Audiotechnologien und Audio-Gadgets, die 2019 in die TECnology Hall of Fame aufgenommen werden</a></li>
<li><a href="../de433956/index.html">Modder haben KI verwendet, um die Textur in Spielen zu verbessern</a></li>
</ul></nav>
</section><br />
<a href="../../allArticles.html"><strong>All Articles</strong></a>
<script src="../../js/main.js"></script>

<!-- Yandex.Metrika counter -->
<script type="text/javascript" >
  (function (d, w, c) {
      (w[c] = w[c] || []).push(function() {
          try {
              w.yaCounter57283870 = new Ya.Metrika({
                  id:57283870,
                  clickmap:true,
                  trackLinks:true,
                  accurateTrackBounce:true,
                  webvisor:true
              });
          } catch(e) { }
      });

      var n = d.getElementsByTagName("script")[0],
          s = d.createElement("script"),
          f = function () { n.parentNode.insertBefore(s, n); };
      s.type = "text/javascript";
      s.async = true;
      s.src = "https://mc.yandex.ru/metrika/watch.js";

      if (w.opera == "[object Opera]") {
          d.addEventListener("DOMContentLoaded", f, false);
      } else { f(); }
  })(document, window, "yandex_metrika_callbacks");
</script>
<noscript><div><img src="https://mc.yandex.ru/watch/57283870" style="position:absolute; left:-9999px;" alt="" /></div></noscript>

<!-- Google Analytics -->
  <script>
    window.ga = function () { ga.q.push(arguments) }; ga.q = []; ga.l = +new Date;
    ga('create', 'UA-134228602-6', 'auto'); ga('send', 'pageview')
  </script>
  <script src="https://www.google-analytics.com/analytics.js" async defer></script>

</section>

<footer class="page-footer">
  <div class="page-footer-legal-info-container page-footer-element">
    <p>
      Weekly-Geekly ES | <span class="page-footer-legal-info-year js-page-footer-legal-info-year">2019</span>
    </p>
  </div>
  <div class="page-footer-counters-container page-footer-element">
    <a class="page-footer-counter-clustrmap" href='#'  title='Visit tracker'><img src='https://clustrmaps.com/map_v2.png?cl=698e5a&w=271&t=t&d=9uU9J9pq8z7k8xEBHYSfs6DenIBAHs3vLIHcPIJW9d0&co=3a3a3a&ct=ffffff'/></a>
  </div>
</footer>
  
</body>

</html>