<!doctype html>
<html class="no-js" lang="en">

<head>
  <!-- Global site tag (gtag.js) - Google Analytics -->
  <script async src="https://www.googletagmanager.com/gtag/js?id=UA-134228602-6"></script>
  <script>
    window.dataLayer = window.dataLayer || [];
    function gtag(){dataLayer.push(arguments);}
    gtag('js', new Date());

    gtag('config', 'UA-134228602-6');
  </script>

  <meta charset="utf-8">
  <meta http-equiv="x-ua-compatible" content="ie=edge">
  <title>üë∂üèº üë®üèº‚Äçü§ù‚Äçüë®üèª üöÜ Des exceptions d√©vastatrices ü¶ä üë©üèº‚Äçü§ù‚Äçüë®üèø üï¥üèª</title>
  <link rel="icon" type="image/x-icon" href="/favicon.ico" />
  <meta name="description" content="Encore une fois, pourquoi il est mauvais de lancer des exceptions dans les destructeurs 


 De nombreux experts C ++ (par exemple, Herb Sutter ) nous ...">
  <meta name="viewport" content="width=device-width, initial-scale=1, shrink-to-fit=no">

  <link rel="stylesheet" href="../../css/main.css">

  <link href="https://fonts.googleapis.com/css?family=Quicksand&display=swap" rel="stylesheet">

  <script src="https://cdnjs.cloudflare.com/ajax/libs/jquery/3.3.1/jquery.min.js"></script>
  <script>window.jQuery || document.write('<script src="../../js/vendors/jquery-3.3.1.min.js"><\/script>')</script>

  <script>document.write('<script src="//pagea' + 'd2.googles' + 'yndication.com/pagea' + 'd/js/a' + 'dsby' + 'google.js"><\/script>')</script>
  <script>
        var superSpecialObject = {};
        superSpecialObject['google_a' + 'd_client'] = 'ca-p' + 'ub-6974184241884155';
        superSpecialObject['enable_page_level_a' + 'ds'] = true;
       (window['a' + 'dsbygoogle'] = window['a' + 'dsbygoogle'] || []).push(superSpecialObject);
  </script>
</head>

<body>
  <!--[if lte IE 9]>
    <p class="browserupgrade">You are using an <strong>outdated</strong> browser. Please <a href="https://browsehappy.com/">upgrade your browser</a> to improve your experience and security.</p>
  <![endif]-->
  <header class="page-header js-page-header">
    <a class="page-header-logo-container" href="https://weekly-geekly-es.github.io/index.html"></a>
    <div class="page-header-text">Geekly articles weekly</div>
  </header>
  <section class="page js-page"><h1>Des exceptions d√©vastatrices</h1><div class="post__body post__body_full"><div class="post__text post__text-html post__text_v1" id="post-content-body" data-io-article-url="https://habr.com/ru/post/433944/"><h2 id="eschyo-raz-o-tom-pochemu-ploho-brosat-isklyucheniya-v-destruktorah">  Encore une fois, pourquoi il est mauvais de lancer des exceptions dans les destructeurs </h2><br><p>  De nombreux experts C ++ (par exemple, <a href="https://translate.googleusercontent.com/translate_c?depth=1&amp;rurl=translate.google.com&amp;sl=ru&amp;sp=nmt4&amp;tl=fr&amp;u=">Herb Sutter</a> ) nous apprennent que lancer des exceptions dans les destructeurs est mauvais, car vous pouvez entrer dans le destructeur pendant la promotion de la pile lorsque l'exception est d√©j√† lev√©e, et si √† ce moment une autre exception est lev√©e, le r√©sultat sera appel√© <em>std :: terminate ()</em> .  La norme de langage C ++ 17 (ci-apr√®s je me r√©f√®re √† la version librement disponible du projet <a href="https://translate.googleusercontent.com/translate_c?depth=1&amp;rurl=translate.google.com&amp;sl=ru&amp;sp=nmt4&amp;tl=fr&amp;u=">N4713</a> ) sur ce sujet nous dit ce qui suit: </p><a name="habracut"></a><br><blockquote>  <strong>18.5.1 La fonction std :: terminate () [except.terminate]</strong> <br><br>  1 Dans certaines situations, la gestion des exceptions doit √™tre abandonn√©e pour les techniques de gestion des erreurs moins subtiles.  [Remarque: <br><br>  Ces situations sont: <br><br>  ... <br><br>  (1.4) lorsque la destruction d'un objet pendant le d√©roulement de la pile (18.2) se termine par le lancement d'une exception, ou <br><br>  ... <br><br>  - note de fin] </blockquote><p>  V√©rifions un exemple simple: </p><br><pre><code class="plaintext hljs">#include &lt;iostream&gt; class PrintInDestructor { public: ~PrintInDestructor() noexcept { std::cerr &lt;&lt; "~PrintInDestructor() invoked\n"; } }; void throw_int_func() { std::cerr &lt;&lt; "throw_int_func() invoked\n"; throw 1; } class ThrowInDestructor { public: ~ThrowInDestructor() noexcept(false) { std::cerr &lt;&lt; "~ThrowInDestructor() invoked\n"; throw_int_func(); } private: PrintInDestructor member_; }; int main(int, char**) { try { ThrowInDestructor bad; throw "BANG!"; } catch (int i) { std::cerr &lt;&lt; "Catched int exception: " &lt;&lt; i &lt;&lt; "\n"; } catch (const char* c) { std::cerr &lt;&lt; "Catched const char* exception: " &lt;&lt; c &lt;&lt; "\n"; } catch (...) { std::cerr &lt;&lt; "Catched unknown exception\n"; } return 0; }</code> </pre> <br><p>  R√©sultat: </p><br><pre> <code class="plaintext hljs">~ThrowInDestructor() invoked throw_int_func() invoked ~PrintInDestructor() invoked terminate called after throwing an instance of 'int' Aborted</code> </pre> <br><p>  Notez que le destructeur <em>PrintInDestructor</em> est toujours appel√©, c'est-√†-dire  apr√®s avoir lev√© la deuxi√®me exception, la promotion de la pile n'est pas interrompue.  La norme (le m√™me paragraphe 18.5.1) √† ce sujet dit ce qui suit: </p><br><blockquote>  2 ... Dans le cas o√π aucun gestionnaire correspondant n'est trouv√©, <br>  il est d√©fini par l'impl√©mentation, que la pile soit d√©roul√©e ou non avant l'appel de std :: terminate ().  Dans <br>  la situation o√π la recherche d'un gestionnaire (18.3) rencontre le bloc le plus √† l'ext√©rieur d'une fonction avec un <br>  sp√©cification d'exception sans lancement (18.4), il est d√©fini par l'impl√©mentation si la pile est d√©roul√©e, <br>  d√©roul√© partiellement ou pas d√©roul√© du tout avant que std :: terminate () soit appel√© ... </blockquote><p>  J'ai test√© cet exemple sur plusieurs versions de <strong>GCC</strong> (8.2, 7.3) et <strong>Clang</strong> (6.0, 5.0), partout o√π la promotion de la pile continue.  Si vous rencontrez un compilateur o√π la d√©finition de l'impl√©mentation est diff√©rente, veuillez en parler dans les commentaires. </p><br><p>  Il convient √©galement de noter que <em>std :: terminate ()</em> est appel√© lorsque la pile est d√©roul√©e uniquement lorsqu'une exception est lev√©e du destructeur.  S'il y a un bloc try / catch √† l'int√©rieur du destructeur qui intercepte l'exception et ne lance plus, cela n'interrompt pas la promotion de la pile de l'exception externe. </p><br><pre> <code class="plaintext hljs">class ThrowCatchInDestructor { public: ~ThrowCatchInDestructor() noexcept(false) { try { throw_int_func(); } catch (int i) { std::cerr &lt;&lt; "Catched int in ~ThrowCatchInDestructor(): " &lt;&lt; i &lt;&lt; "\n"; } } private: PrintInDestructor member_; }; int main(int, char**) { try { ThrowCatchInDestructor good; std::cerr &lt;&lt; "ThrowCatchInDestructor instance created\n"; throw "BANG!"; } catch (int i) { std::cerr &lt;&lt; "Catched int exception: " &lt;&lt; i &lt;&lt; "\n"; } catch (const char* s) { std::cerr &lt;&lt; "Catched const char* exception: " &lt;&lt; s &lt;&lt; "\n"; } catch (...) { std::cerr &lt;&lt; "Catched unknown exception\n"; } return 0; }</code> </pre> <br><p>  affiche </p><br><pre> <code class="plaintext hljs">ThrowCatchInDestructor instance created throw_int_func() invoked Catched int in ~ThrowCatchInDestructor(): 1 ~PrintInDestructor() invoked Catched const char* exception: BANG!</code> </pre> <br><p>  Comment √©viter les situations d√©sagr√©ables?  En th√©orie, tout est simple: ne lancez jamais d'exceptions dans le destructeur.  Cependant, dans la pratique, il n'est pas si simple de r√©aliser magnifiquement et √©l√©gamment cette simple exigence. </p><br><h2 id="esli-nelzya-no-ochen-hochetsya">  Si vous ne pouvez pas, mais que vous voulez vraiment ... </h2><br><blockquote>  Je noterai imm√©diatement que je n'essaie pas de justifier la lev√©e d'exceptions du destructeur, et √† la suite de Sutter, Meyers et d'autres gourous C ++, je vous exhorte <strong>√† essayer de</strong> ne jamais faire cela (au moins dans le nouveau code).  N√©anmoins, dans la pratique, un programmeur peut tr√®s bien rencontrer du code h√©rit√©, ce qui n'est pas si facile √† conduire √† des normes √©lev√©es.  De plus, les techniques souvent d√©crites ci-dessous peuvent √™tre utiles pendant le processus de d√©bogage. </blockquote><p>  Par exemple, nous d√©veloppons une biblioth√®que avec une classe wrapper qui encapsule le travail avec une certaine ressource.  Conform√©ment aux principes de RAII, nous saisissons la ressource dans le constructeur et devons la lib√©rer dans le destructeur.  Mais que faire si une tentative de lib√©ration d'une ressource √©choue?  Options pour r√©soudre ce probl√®me: </p><br><ul><li>  Ignorez l'erreur.  Mauvais, car nous cachons un probl√®me qui pourrait affecter d'autres parties du syst√®me. </li><li>  √âcrivez dans le journal.  Mieux que de simplement l'ignorer, mais toujours mauvais, car  notre biblioth√®que ne sait rien des politiques de journalisation adopt√©es dans le syst√®me qui l'utilise.  Le journal standard peut √™tre redirig√© vers / dev / null, √† la suite de quoi, encore une fois, nous ne verrons pas d'erreur. </li><li>  Prenez la version de la ressource dans une fonction distincte qui renvoie une valeur ou l√®ve une exception et forcez l'utilisateur de la classe √† l'appeler par lui-m√™me.  C'est mauvais, car l'utilisateur peut oublier de le faire et nous recevrons une fuite de ressources. </li><li>  Jetez une exception.  Bon dans les cas ordinaires, comme  l'utilisateur de classe peut intercepter l'exception et obtenir des informations sur l'erreur de mani√®re standard.  Mauvais pendant la promotion de la pile, car  conduit √† <em>std :: terminate ()</em> . </li></ul><br><p>  Comment savoir si nous sommes actuellement en train de promouvoir la pile par exception ou non?  En C ++, il existe une fonction sp√©ciale <em>std :: uncaught_exception () pour cela</em> .  Avec son aide, nous pouvons lever une exception en toute s√©curit√© dans une situation normale, ou faire quelque chose de moins correct, mais sans conduire √† lever une exception pendant la promotion de la pile. </p><br><pre> <code class="plaintext hljs">class ThrowInDestructor { public: ~ThrowInDestructor() noexcept(false) { if (std::uncaught_exception()) { std::cerr &lt;&lt; "~ThrowInDestructor() stack unwinding, not throwing\n"; } else { std::cerr &lt;&lt; "~ThrowInDestructor() normal case, throwing\n"; throw_int_func(); } } private: PrintInDestructor member_; }; int main(int, char**) { try { ThrowInDestructor normal; std::cerr &lt;&lt; "ThrowInDestructor normal destruction\n"; } catch (int i) { std::cerr &lt;&lt; "Catched int exception: " &lt;&lt; i &lt;&lt; "\n"; } try { ThrowInDestructor stack_unwind; std::cerr &lt;&lt; "ThrowInDestructor stack unwinding\n"; throw "BANG!"; } catch (int i) { std::cerr &lt;&lt; "Catched int exception: " &lt;&lt; i &lt;&lt; "\n"; } catch (const char* s) { std::cerr &lt;&lt; "Catched const char* exception: " &lt;&lt; s &lt;&lt; "\n"; } catch (...) { std::cerr &lt;&lt; "Catched unknown exception\n"; } return 0; }</code> </pre> <br><p>  R√©sultat: </p><br><pre> <code class="plaintext hljs">ThrowInDestructor normal destruction ~ThrowInDestructor() normal case, throwing throw_int_func() invoked ~PrintInDestructor() invoked Catched int exception: 1 ThrowInDestructor stack unwinding ~ThrowInDestructor() stack unwinding, not throwing ~PrintInDestructor() invoked Catched const char* exception: BANG!</code> </pre> <br><p>  Notez que la fonction <em>std :: uncaught_exception ()</em> est <em>obsol√®te</em> depuis la norme C ++ 17, par cons√©quent, pour compiler l'exemple, le vorning correspondant doit √™tre supprim√© (voir le <a href="https://translate.googleusercontent.com/translate_c?depth=1&amp;rurl=translate.google.com&amp;sl=ru&amp;sp=nmt4&amp;tl=fr&amp;u=">r√©f√©rentiel avec des exemples de l'article</a> ). </p><br><p>  Le probl√®me avec cette fonction est qu'elle v√©rifie si nous sommes en train de faire tourner la pile par exception.  Mais il est impossible de comprendre si le destructeur actuel est appel√© pendant le processus de promotion de la pile.  Par cons√©quent, s'il existe une promotion de pile, mais que le destructeur d'un objet est appel√© normalement, <em>std :: uncaught_exception ()</em> renverra toujours <em>true</em> . </p><br><pre> <code class="plaintext hljs">class MayThrowInDestructor { public: ~MayThrowInDestructor() noexcept(false) { if (std::uncaught_exception()) { std::cerr &lt;&lt; "~MayThrowInDestructor() stack unwinding, not throwing\n"; } else { std::cerr &lt;&lt; "~MayThrowInDestructor() normal case, throwing\n"; throw_int_func(); } } }; class ThrowCatchInDestructor { public: ~ThrowCatchInDestructor() noexcept(false) { try { MayThrowInDestructor may_throw; } catch (int i) { std::cerr &lt;&lt; "Catched int in ~ThrowCatchInDestructor(): " &lt;&lt; i &lt;&lt; "\n"; } } private: PrintInDestructor member_; }; int main(int, char**) { try { ThrowCatchInDestructor stack_unwind; std::cerr &lt;&lt; "ThrowInDestructor stack unwinding\n"; throw "BANG!"; } catch (int i) { std::cerr &lt;&lt; "Catched int exception: " &lt;&lt; i &lt;&lt; "\n"; } catch (const char* s) { std::cerr &lt;&lt; "Catched const char* exception: " &lt;&lt; s &lt;&lt; "\n"; } catch (...) { std::cerr &lt;&lt; "Catched unknown exception\n"; } return 0; }</code> </pre> <br><p>  R√©sultat: </p><br><pre> <code class="plaintext hljs">ThrowInDestructor stack unwinding ~MayThrowInDestructor() stack unwinding, not throwing ~PrintInDestructor() invoked Catched const char* exception: BANG!</code> </pre> <br><p>  Dans la nouvelle norme C ++ 17, la fonction <em>std :: uncaught_exceptions () a</em> √©t√© introduite pour remplacer <em>std :: uncaught_exception ()</em> (notez le pluriel) qui, au lieu d'une valeur bool√©enne, renvoie le nombre d'exceptions actuellement actives (voici une <a href="https://translate.googleusercontent.com/translate_c?depth=1&amp;rurl=translate.google.com&amp;sl=ru&amp;sp=nmt4&amp;tl=fr&amp;u=">justification</a> d√©taill√©e). </p><br><p>  Voici comment le probl√®me d√©crit ci-dessus est r√©solu avec <em>std :: uncaught_exceptions ()</em> : </p><br><pre> <code class="plaintext hljs">class MayThrowInDestructor { public: MayThrowInDestructor() : exceptions_(std::uncaught_exceptions()) {} ~MayThrowInDestructor() noexcept(false) { if (std::uncaught_exceptions() &gt; exceptions_) { std::cerr &lt;&lt; "~MayThrowInDestructor() stack unwinding, not throwing\n"; } else { std::cerr &lt;&lt; "~MayThrowInDestructor() normal case, throwing\n"; throw_int_func(); } } private: int exceptions_; }; class ThrowCatchInDestructor { public: ~ThrowCatchInDestructor() noexcept(false) { try { MayThrowInDestructor may_throw; } catch (int i) { std::cerr &lt;&lt; "Catched int in ~ThrowCatchInDestructor(): " &lt;&lt; i &lt;&lt; "\n"; } } private: PrintInDestructor member_; }; int main(int, char**) { try { ThrowCatchInDestructor stack_unwind; std::cerr &lt;&lt; "ThrowInDestructor stack unwinding\n"; throw "BANG!"; } catch (int i) { std::cerr &lt;&lt; "Catched int exception: " &lt;&lt; i &lt;&lt; "\n"; } catch (const char* s) { std::cerr &lt;&lt; "Catched const char* exception: " &lt;&lt; s &lt;&lt; "\n"; } catch (...) { std::cerr &lt;&lt; "Catched unknown exception\n"; } return 0; }</code> </pre> <br><p>  R√©sultat: </p><br><pre> <code class="plaintext hljs">ThrowInDestructor stack unwinding ~MayThrowInDestructor() normal case, throwing throw_int_func() invoked Catched int in ~ThrowCatchInDestructor(): 1 ~PrintInDestructor() invoked Catched const char* exception: BANG!</code> </pre> <br><h2 id="kogda-ochen-ochen-hochetsya-vybrosit-srazu-neskolko-isklyucheniy">  Quand j'ai vraiment, vraiment envie de lever quelques exceptions √† la fois </h2><br><p>  <em>std :: uncaught_exceptions ()</em> √©vite d'appeler <em>std :: terminate ()</em> , mais n'aide pas √† g√©rer correctement plusieurs exceptions.  Id√©alement, j'aimerais avoir un m√©canisme qui me permettrait d'enregistrer toutes les exceptions lev√©es, puis de les traiter en un seul endroit. </p><br><blockquote>  Je tiens √† rappeler une fois de plus que le m√©canisme propos√© par moi ci-dessous ne sert qu'√† d√©montrer le concept et n'est pas recommand√© pour une utilisation dans le vrai code industriel. </blockquote><p>  L'essence de l'id√©e est d'attraper des exceptions et de les enregistrer dans un conteneur, puis de les obtenir et de les traiter une par une.  Afin d'enregistrer les objets d'exception, C ++ a un type sp√©cial <em>std :: exception_ptr</em> .  La structure de type dans la norme n'est pas divulgu√©e, mais il est dit qu'elle est essentiellement <em>shared_ptr</em> par objet d'exception. </p><br><p>  Comment alors traiter ces exceptions?  Il existe une fonction <em>std :: rethrow_exception () pour cela</em> , qui prend un pointeur <em>std :: exception_ptr</em> et l√®ve l'exception correspondante.  Nous avons seulement besoin de l'attraper avec la section catch correspondante et de la traiter, apr√®s quoi nous pouvons passer √† l'objet d'exception suivant. </p><br><pre> <code class="plaintext hljs">using exceptions_queue = std::stack&lt;std::exception_ptr&gt;; // Get exceptions queue for current thread exceptions_queue&amp; get_queue() { thread_local exceptions_queue queue_; return queue_; } // Invoke functor and save exception in queue void safe_invoke(std::function&lt;void()&gt; f) noexcept { try { f(); } catch (...) { get_queue().push(std::current_exception()); } } class ThrowInDestructor { public: ~ThrowInDestructor() noexcept { std::cerr &lt;&lt; "~ThrowInDestructor() invoked\n"; safe_invoke([]() { throw_int_func(); }); } private: PrintInDestructor member_; }; int main(int, char**) { safe_invoke([]() { ThrowInDestructor bad; throw "BANG!"; }); auto&amp; q = get_queue(); while (!q.empty()) { try { std::exception_ptr ex = q.top(); q.pop(); if (ex != nullptr) { std::rethrow_exception(ex); } } catch (int i) { std::cerr &lt;&lt; "Catched int exception: " &lt;&lt; i &lt;&lt; "\n"; } catch (const char* s) { std::cerr &lt;&lt; "Catched const char* exception: " &lt;&lt; s &lt;&lt; "\n"; } catch (...) { std::cerr &lt;&lt; "Catched unknown exception\n"; } } return 0; }</code> </pre> <br><p>  R√©sultat: </p><br><pre> <code class="plaintext hljs">~ThrowInDestructor() invoked throw_int_func() invoked ~PrintInDestructor() invoked Catched const char* exception: BANG! Catched int exception: 1</code> </pre> <br><p>  Dans l'exemple ci-dessus, la pile est utilis√©e pour enregistrer les objets d'exception, cependant, la gestion des exceptions sera effectu√©e selon le principe FIFO (c'est-√†-dire, logiquement, c'est la file d'attente - l'exception lev√©e en premier sera la premi√®re √† √™tre trait√©e). </p><br><h2 id="vyvody">  Conclusions </h2><br><p>  Lancer des exceptions dans les destructeurs d'objets est vraiment une mauvaise id√©e, et dans tout nouveau code, je recommande fortement de ne pas le faire en d√©clarant <em>noexcept</em> destructors.  Cependant, avec la prise en charge et le d√©bogage du code h√©rit√©, il peut √™tre n√©cessaire de g√©rer correctement les exceptions lev√©es par les destructeurs, y compris pendant la promotion de la pile, et le C ++ moderne nous fournit des m√©canismes pour cela.  J'esp√®re que les id√©es pr√©sent√©es dans l'article vous aideront sur cette voie difficile. </p><br><h2 id="ssylki">  Les r√©f√©rences </h2><br><p>  <a href="https://translate.googleusercontent.com/translate_c?depth=1&amp;rurl=translate.google.com&amp;sl=ru&amp;sp=nmt4&amp;tl=fr&amp;u=">R√©f√©rentiel avec des exemples de l'article</a> </p></div></div><p>Source: <a rel="nofollow" href="https://habr.com/ru/post/fr433944/">https://habr.com/ru/post/fr433944/</a></p>
<section class="more-articles-navigation-panel js-more-articles-navigation-panel">
<h4>More articles:</h4>
<nav class="list-of-articles-container js-list-of-articles-container"><ul class="list-of-pages js-list-of-pages">
<li><a href="../fr433932/index.html">Nous tirons dans le pied, traitant les donn√©es d'entr√©e</a></li>
<li><a href="../fr433934/index.html">SAFe ou Scaled Agile Framework</a></li>
<li><a href="../fr433936/index.html">Vous cherchez un cadeau high-tech pour un enfant? Pensez √† un terrain de jeu, pas √† un parc</a></li>
<li><a href="../fr433938/index.html">Comment Yandex et Google r√©sument l'ann√©e</a></li>
<li><a href="../fr433940/index.html">Combien co√ªte Review dans l'AppStore</a></li>
<li><a href="../fr433946/index.html">Aide-m√©moire pour l'intelligence artificielle - jetez l'exc√©dent, enseignez l'essentiel. Technique de traitement des s√©quences de formation</a></li>
<li><a href="../fr433948/index.html">Comment rendre le paiement plus pratique: l'exp√©rience d'un fournisseur IaaS</a></li>
<li><a href="../fr433952/index.html">10 raisons de choisir une solution pour SAP HANA de HPE. 2e partie</a></li>
<li><a href="../fr433954/index.html">Huit technologies audio et gadgets audio qui entreront au Temple de la renomm√©e de TECnology en 2019</a></li>
<li><a href="../fr433956/index.html">Les modders ont utilis√© l'IA pour am√©liorer la texture dans les jeux</a></li>
</ul></nav>
</section><br />
<a href="../../allArticles.html"><strong>All Articles</strong></a>
<script src="../../js/main.js"></script>

<!-- Yandex.Metrika counter -->
<script type="text/javascript" >
  (function (d, w, c) {
      (w[c] = w[c] || []).push(function() {
          try {
              w.yaCounter57283870 = new Ya.Metrika({
                  id:57283870,
                  clickmap:true,
                  trackLinks:true,
                  accurateTrackBounce:true,
                  webvisor:true
              });
          } catch(e) { }
      });

      var n = d.getElementsByTagName("script")[0],
          s = d.createElement("script"),
          f = function () { n.parentNode.insertBefore(s, n); };
      s.type = "text/javascript";
      s.async = true;
      s.src = "https://mc.yandex.ru/metrika/watch.js";

      if (w.opera == "[object Opera]") {
          d.addEventListener("DOMContentLoaded", f, false);
      } else { f(); }
  })(document, window, "yandex_metrika_callbacks");
</script>
<noscript><div><img src="https://mc.yandex.ru/watch/57283870" style="position:absolute; left:-9999px;" alt="" /></div></noscript>

<!-- Google Analytics -->
  <script>
    window.ga = function () { ga.q.push(arguments) }; ga.q = []; ga.l = +new Date;
    ga('create', 'UA-134228602-6', 'auto'); ga('send', 'pageview')
  </script>
  <script src="https://www.google-analytics.com/analytics.js" async defer></script>

</section>

<footer class="page-footer">
  <div class="page-footer-legal-info-container page-footer-element">
    <p>
      Weekly-Geekly ES | <span class="page-footer-legal-info-year js-page-footer-legal-info-year">2019</span>
    </p>
  </div>
  <div class="page-footer-counters-container page-footer-element">
    <a class="page-footer-counter-clustrmap" href='#'  title='Visit tracker'><img src='https://clustrmaps.com/map_v2.png?cl=698e5a&w=271&t=t&d=9uU9J9pq8z7k8xEBHYSfs6DenIBAHs3vLIHcPIJW9d0&co=3a3a3a&ct=ffffff'/></a>
  </div>
</footer>
  
</body>

</html>