<!doctype html>
<html class="no-js" lang="en">

<head>
  <!-- Global site tag (gtag.js) - Google Analytics -->
  <script async src="https://www.googletagmanager.com/gtag/js?id=UA-134228602-6"></script>
  <script>
    window.dataLayer = window.dataLayer || [];
    function gtag(){dataLayer.push(arguments);}
    gtag('js', new Date());

    gtag('config', 'UA-134228602-6');
  </script>

  <meta charset="utf-8">
  <meta http-equiv="x-ua-compatible" content="ie=edge">
  <title>üé± ‚úãüèø üë©üèª‚Äç‚öïÔ∏è [DotNetBook] √âv√©nements d'exception et comment obtenir StackOverflow et ExecutionEngineException √† partir de z√©ro ü§µüèΩ üéí üò¶</title>
  <link rel="icon" type="image/x-icon" href="/favicon.ico" />
  <meta name="description" content="√âv√©nements d'exception 


 Dans le cas g√©n√©ral, nous ne connaissons pas toujours les exceptions qui se produiront dans nos programmes, car nous utilis...">
  <meta name="viewport" content="width=device-width, initial-scale=1, shrink-to-fit=no">

  <link rel="stylesheet" href="../../css/main.css">

  <link href="https://fonts.googleapis.com/css?family=Quicksand&display=swap" rel="stylesheet">

  <script src="https://cdnjs.cloudflare.com/ajax/libs/jquery/3.3.1/jquery.min.js"></script>
  <script>window.jQuery || document.write('<script src="../../js/vendors/jquery-3.3.1.min.js"><\/script>')</script>

  <script>document.write('<script src="//pagea' + 'd2.googles' + 'yndication.com/pagea' + 'd/js/a' + 'dsby' + 'google.js"><\/script>')</script>
  <script>
        var superSpecialObject = {};
        superSpecialObject['google_a' + 'd_client'] = 'ca-p' + 'ub-6974184241884155';
        superSpecialObject['enable_page_level_a' + 'ds'] = true;
       (window['a' + 'dsbygoogle'] = window['a' + 'dsbygoogle'] || []).push(superSpecialObject);
  </script>
</head>

<body>
  <!--[if lte IE 9]>
    <p class="browserupgrade">You are using an <strong>outdated</strong> browser. Please <a href="https://browsehappy.com/">upgrade your browser</a> to improve your experience and security.</p>
  <![endif]-->
  <header class="page-header js-page-header">
    <a class="page-header-logo-container" href="https://weekly-geekly-es.github.io/index.html"></a>
    <div class="page-header-text">Geekly articles weekly</div>
  </header>
  <section class="page js-page"><h1>[DotNetBook] √âv√©nements d'exception et comment obtenir StackOverflow et ExecutionEngineException √† partir de z√©ro</h1><div class="post__body post__body_full"><div class="post__text post__text-html post__text_v1" id="post-content-body" data-io-article-url="https://habr.com/ru/company/clrium/blog/419929/"><img width="350" src="https://habrastorage.org/webt/vh/7j/tq/vh7jtqhzbne4h3rjhprca2pruhu.png" align="left"><br><h2 id="sobytiya-ob-isklyuchitelnyh-situaciyah">  √âv√©nements d'exception </h2><br><p> Dans le cas g√©n√©ral, nous ne connaissons pas toujours les exceptions qui se produiront dans nos programmes, car nous utilisons presque toujours quelque chose qui est √©crit par d'autres personnes et qui se trouve dans d'autres sous-syst√®mes et biblioth√®ques.  Non seulement il peut y avoir une vari√©t√© de situations dans votre propre code, dans le code d'autres biblioth√®ques, il y a aussi de nombreux probl√®mes associ√©s √† l'ex√©cution de code dans des domaines isol√©s.  Et juste dans ce cas, il serait extr√™mement utile de pouvoir recevoir des donn√©es sur le fonctionnement du code isol√©.  Apr√®s tout, une situation peut √™tre bien r√©elle lorsque du code tiers intercepte toutes les erreurs sans exception, noyant leur <code>fault</code> bloc: </p><br><pre> <code class="plaintext hljs">try { // ... } catch { // do nothing, just to make code call more safe }</code> </pre> <br><p>  Dans une telle situation, il peut s'av√©rer que l'ex√©cution du code n'est plus aussi s√ªre qu'elle en a l'air, mais nous n'avons aucun message concernant des probl√®mes.  La deuxi√®me option est lorsque l'application supprime une exception, m√™me l√©gale.  Et le r√©sultat - l'exception suivante dans un endroit al√©atoire entra√Ænera un plantage de l'application dans un certain avenir √† partir d'une erreur apparemment al√©atoire.  Ici, je voudrais avoir une id√©e de l'arri√®re-plan de cette erreur.  Quel est le cours des √©v√©nements a conduit √† cette situation.  Et une fa√ßon de rendre cela possible consiste √† utiliser des √©v√©nements suppl√©mentaires li√©s √† des situations exceptionnelles: <code>AppDomain.FirstChanceException</code> et <code>AppDomain.UnhandledException</code> . </p><br><blockquote><h3>  Remarque </h3><br>  Le chapitre publi√© sur Habr√© n'est pas mis √† jour et, probablement, est un peu d√©pass√©.  Et par cons√©quent, veuillez vous tourner vers l'original pour un texte plus r√©cent: <br><br><ul><li><img src="https://habrastorage.org/webt/3q/6g/qa/3q6gqaz40qx-jzscjf3jbxatxhg.png">  Livre CLR: <a href="https://translate.googleusercontent.com/translate_c?depth=1&amp;rurl=translate.google.com&amp;sl=ru&amp;sp=nmt4&amp;tl=fr&amp;u=">GitHub, table des mati√®res</a> </li><li><img src="https://habrastorage.org/webt/3q/6g/qa/3q6gqaz40qx-jzscjf3jbxatxhg.png">  Livre CLR: <a href="">GitHub, chapitre</a> </li><li><img src="https://habrastorage.org/webt/eo/6g/eo/eo6geog0tg5ernqmv2lcmufefta.png">  Version 0.5.2 livres, PDF: <a href="">version GitHub</a> </li></ul><br></blockquote><p> <a href="https://translate.googleusercontent.com/translate_c?depth=1&amp;rurl=translate.google.com&amp;sl=ru&amp;sp=nmt4&amp;tl=fr&amp;u="><img src="https://habrastorage.org/getpro/habr/post_images/97f/1d3/cf0/97f1d3cf0e2a6bf007066eb60a789c31.png"></a> </p><a name="habracut"></a><br><p>  En fait, lorsque vous "lancez une exception", la m√©thode habituelle d'un sous-syst√®me <code>Throw</code> interne est appel√©e, qui √† l'int√©rieur d'elle-m√™me effectue les op√©rations suivantes: </p><br><ul><li>  L√®ve <code>AppDomain.FirstChanceException</code> </li><li>  Recherche les filtres correspondants dans la cha√Æne des gestionnaires </li><li>  Force le gestionnaire √† pr√©-rouler la pile dans le cadre souhait√©. </li><li>  Si aucun gestionnaire n'a √©t√© trouv√©, une <code>AppDomain.UnhandledException</code> est <code>AppDomain.UnhandledException</code> , ce qui bloque le thread dans lequel l'exception s'est produite. </li></ul><br><p>  Il faut imm√©diatement faire une r√©serve en r√©pondant √† une question qui tourmente de nombreux esprits: est-il possible d'annuler en quelque sorte l'exception qui s'est produite dans le code non contr√¥l√© qui est ex√©cut√© dans le domaine isol√© sans rompre ainsi le fil dans lequel cette exception a √©t√© lanc√©e?  La r√©ponse est concise et simple: non.  Si une exception n'est pas intercept√©e sur l'ensemble des m√©thodes appel√©es, elle ne peut pas √™tre g√©r√©e en principe.  Sinon, une situation √©trange se produit: si nous utilisons une exception <code>AppDomain.FirstChanceException</code> g√©rer (une sorte de <code>catch</code> synth√©tique), dans quel cadre la pile de threads doit-elle revenir?  Comment d√©finir cela dans le cadre des r√®gles .NET CLR?  Pas question.  Ce n'est tout simplement pas possible.  La seule chose que nous pouvons faire est d'enregistrer les informations re√ßues pour de futures recherches. </p><br><p>  La deuxi√®me chose √† parler de ¬´√† terre¬ª est la raison pour laquelle ces √©v√©nements ont √©t√© pr√©sent√©s non pas √† <code>Thread</code> , mais √† <code>AppDomain</code> .  Apr√®s tout, si vous suivez la logique, des exceptions surviennent o√π?  Dans le flux d'ex√©cution des commandes.  C'est-√†-dire  en fait <code>Thread</code> .  Alors pourquoi le domaine a-t-il des probl√®mes?  La r√©ponse est tr√®s simple: dans quelles situations <code>AppDomain.FirstChanceException</code> et <code>AppDomain.UnhandledException</code> ont-ils √©t√© <code>AppDomain.FirstChanceException</code> ?  Entre autres choses - pour cr√©er des sandbox pour les plugins.  C'est-√†-dire  pour les situations o√π un certain <code>AppDomain</code> est configur√© pour PartialTrust.  Tout peut arriver √† l'int√©rieur de cet AppDomain: des threads peuvent y √™tre cr√©√©s √† tout moment, ou des threads existants de ThreadPool peuvent √™tre utilis√©s.  Ensuite, il s'av√®re que nous, √©tant en dehors de ce processus (nous n'avons pas √©crit ce code), nous ne pouvons pas souscrire aux √©v√©nements des flux internes.  Tout simplement parce que nous n'avons aucune id√©e des flux qui y ont √©t√© cr√©√©s.  Mais nous sommes garantis d'avoir un <code>AppDomain</code> qui organise le bac √† sable et le lien vers lequel nous avons. </p><br><p>  Donc, en fait, nous avons deux √©v√©nements r√©gionaux: quelque chose s'est pass√© qui n'√©tait pas suppos√© ( <code>FirstChanceExecption</code> ) et "tout va mal", personne n'a g√©r√© l'exception: cela n'a pas √©t√© fourni.  Par cons√©quent, le flux d'ex√©cution des commandes n'a pas de sens et il ( <code>Thread</code> ) sera exp√©di√©. </p><br><p>  Que peut-on obtenir en ayant ces √©v√©nements et pourquoi est-il mauvais que les d√©veloppeurs contournent ces √©v√©nements? </p><br><h3 id="appdomainfirstchanceexception">  AppDomain.FirstChanceException </h3><br><p>  Cet √©v√©nement est par nature purement informatif et ne peut pas √™tre ¬´trait√©¬ª.  Sa t√¢che est de vous informer qu'une exception s'est produite dans ce domaine et il commencera √† √™tre trait√© par le code d'application apr√®s le traitement de l'√©v√©nement.  Son ex√©cution comporte quelques fonctionnalit√©s dont il faut se souvenir lors de la conception du processeur. </p><br><p>  Mais regardons d'abord un exemple synth√©tique simple de son traitement: </p><br><pre> <code class="plaintext hljs">void Main() { var counter = 0; AppDomain.CurrentDomain.FirstChanceException += (_, args) =&gt; { Console.WriteLine(args.Exception.Message); if(++counter == 1) { throw new ArgumentOutOfRangeException(); } }; throw new Exception("Hello!"); }</code> </pre> <br><p>  Qu'est-ce qui est remarquable avec ce code?  Partout o√π du code l√®ve une exception, la premi√®re chose qui se produit est de le connecter √† la console.  C'est-√†-dire  m√™me si vous oubliez ou ne pouvez pas envisager de g√©rer un type d'exception, il appara√Ætra toujours dans le journal des √©v√©nements que vous organisez.  La seconde est une condition quelque peu √©trange pour lever une exception interne.  Le fait est qu'√† l'int√©rieur du gestionnaire <code>FirstChanceException</code> vous ne pouvez pas simplement lancer et <code>FirstChanceException</code> une exception de plus.  Au contraire, m√™me ceci: √† l'int√©rieur du gestionnaire FirstChanceException, vous n'√™tes <em>pas en mesure</em> de lever au moins une exception.  Si vous le faites, il y a deux √©v√©nements possibles.  Au d√©but, s'il n'y avait pas de <code>if(++counter == 1)</code> , nous obtiendrions une <code>FirstChanceException</code> infinie pour une toute nouvelle <code>ArgumentOutOfRangeException</code> .  Qu'est-ce que cela signifie?  Cela signifie qu'√† un certain stade, nous aurions une <code>StackOverflowException</code> : <code>throw new Exception("Hello!")</code> <code>FirstChanceException</code> m√©thode CLR Throw, qui l√®ve <code>FirstChanceException</code> , qui l√®ve d√©j√† <code>Throw</code> pour <code>ArgumentOutOfRangeException</code> , puis r√©cursive.  La deuxi√®me option - nous nous sommes d√©fendus par la profondeur de la r√©cursivit√© en utilisant la <code>counter</code> condition.  C'est-√†-dire  dans ce cas, nous lan√ßons une exception une seule fois.  Le r√©sultat est plus qu'inattendu: nous obtenons une exception qui fonctionne r√©ellement √† l'int√©rieur de l'instruction <code>Throw</code> .  Et qu'est-ce qui convient le mieux √† ce type d'erreur?  Selon ECMA-335, si une instruction a √©t√© lanc√©e dans une exception, une <code>ExecutionEngineException</code> doit √™tre lev√©e!  Mais nous ne sommes pas en mesure de g√©rer cette situation exceptionnelle.  Cela conduit √† un crash complet de l'application.  Quelles sont les options de traitement s√©curitaires dont nous disposons? </p><br><p>  La premi√®re chose qui me vient √† l'esprit est de d√©finir un bloc <code>try-catch</code> sur tout le code du gestionnaire <code>FirstChanceException</code> : </p><br><pre> <code class="plaintext hljs">void Main() { var fceStarted = false; var sync = new object(); EventHandler&lt;FirstChanceExceptionEventArgs&gt; handler; handler = new EventHandler&lt;FirstChanceExceptionEventArgs&gt;((_, args) =&gt; { lock (sync) { if (fceStarted) { //     - ,        -      , //   try  . Console.WriteLine($"FirstChanceException inside FirstChanceException ({args.Exception.GetType().FullName})"); return; } fceStarted = true; try { //     . ,   Console.WriteLine(args.Exception.Message); throw new ArgumentOutOfRangeException(); } catch (Exception exception) { //       Console.WriteLine("Success"); } finally { fceStarted = false; } } }); AppDomain.CurrentDomain.FirstChanceException += handler; try { throw new Exception("Hello!"); } finally { AppDomain.CurrentDomain.FirstChanceException -= handler; } } OUTPUT: Hello! Specified argument was out of the range of valid values. FirstChanceException inside FirstChanceException (System.ArgumentOutOfRangeException) Success !Exception: Hello!</code> </pre> <br><p>  C'est-√†-dire  d'une part, nous avons le code pour g√©rer l'√©v√©nement <code>FirstChanceException</code> , et d'autre part, nous avons du code suppl√©mentaire pour g√©rer les exceptions dans la <code>FirstChanceException</code> elle-m√™me.  Cependant, les techniques de journalisation pour les deux situations doivent √™tre diff√©rentes.  Si la journalisation du traitement des √©v√©nements peut se d√©rouler comme vous le souhaitez, le traitement des erreurs de logique de traitement <code>FirstChanceException</code> doit aller sans exception en principe.  La deuxi√®me chose que vous avez probablement remarqu√©e est la synchronisation entre les threads.  Cela peut soulever la question: pourquoi est-il ici si une exception est lev√©e dans un thread, ce qui signifie que <code>FirstChanceException</code> doit √™tre thread-safe.  Cependant, tout n'est pas si gai.  <code>FirstChanceException</code> nous avons chez AppDomain.  Et cela signifie qu'il se produit pour tout thread d√©marr√© dans un domaine particulier.  C'est-√†-dire  si nous avons un domaine dans lequel plusieurs threads sont d√©marr√©s, <code>FirstChanceException</code> peut aller en parall√®le.  Et cela signifie que nous devons en quelque sorte nous prot√©ger avec la synchronisation: par exemple, en utilisant le <code>lock</code> . </p><br><p>  La deuxi√®me fa√ßon consiste √† essayer de d√©tourner le traitement vers un thread voisin qui appartient √† un domaine d'application diff√©rent.  Cependant, il convient de mentionner qu'avec une telle impl√©mentation, nous devons cr√©er un domaine d√©di√© sp√©cifiquement pour cette t√¢che afin qu'il ne fonctionne pas afin que d'autres flux qui fonctionnent puissent mettre ce domaine: </p><br><pre> <code class="plaintext hljs">static void Main() { using (ApplicationLogger.Go(AppDomain.CurrentDomain)) { throw new Exception("Hello!"); } } public class ApplicationLogger : MarshalByRefObject { ConcurrentQueue&lt;Exception&gt; queue = new ConcurrentQueue&lt;Exception&gt;(); CancellationTokenSource cancellation; ManualResetEvent @event; public void LogFCE(Exception message) { queue.Enqueue(message); } private void StartThread() { cancellation = new CancellationTokenSource(); @event = new ManualResetEvent(false); var thread = new Thread(() =&gt; { while (!cancellation.IsCancellationRequested) { if (queue.TryDequeue(out var exception)) { Console.WriteLine(exception.Message); } Thread.Yield(); } @event.Set(); }); thread.Start(); } private void StopAndWait() { cancellation.Cancel(); @event.WaitOne(); } public static IDisposable Go(AppDomain observable) { var dom = AppDomain.CreateDomain("ApplicationLogger", null, new AppDomainSetup { ApplicationBase = AppDomain.CurrentDomain.BaseDirectory, }); var proxy = (ApplicationLogger)dom.CreateInstanceAndUnwrap(typeof(ApplicationLogger).Assembly.FullName, typeof(ApplicationLogger).FullName); proxy.StartThread(); var subscription = new EventHandler&lt;FirstChanceExceptionEventArgs&gt;((_, args) =&gt; { proxy.LogFCE(args.Exception); }); observable.FirstChanceException += subscription; return new Subscription(() =&gt; { observable.FirstChanceException -= subscription; proxy.StopAndWait(); }); } private class Subscription : IDisposable { Action act; public Subscription (Action act) { this.act = act; } public void Dispose() { act(); } } }</code> </pre> <br><p>  Dans ce cas, la gestion de <code>FirstChanceException</code> est aussi s√ªre que possible: dans le thread voisin appartenant au domaine voisin.  Dans ce cas, les erreurs de traitement d'un message ne peuvent pas provoquer de flux de travail d'application.  De plus, vous pouvez √©couter s√©par√©ment l'exception UnhandledException du domaine de journalisation des messages: des erreurs fatales lors de la journalisation ne feront pas tomber l'application enti√®re. </p><br><h3 id="appdomainunhandledexception">  AppDomain.UnhandledException </h3><br><p>  Le deuxi√®me message que nous pouvons attraper et qui traite de la gestion des exceptions est <code>AppDomain.UnhandledException</code> .  Ce message est une tr√®s mauvaise nouvelle pour nous car cela signifie qu'il n'y avait personne qui pouvait trouver un moyen de g√©rer l'erreur dans un certain thread.  De plus, si une telle situation s'est produite, tout ce que nous pouvons faire est de "clarifier" les cons√©quences d'une telle erreur.  C'est-√†-dire  de quelque mani√®re que ce soit pour nettoyer les ressources appartenant uniquement √† ce flux, le cas √©ch√©ant.  Cependant, une situation encore meilleure consiste √† g√©rer les exceptions √† la racine des threads sans bloquer le thread.  C'est-√†-dire  mettre essentiellement <code>try-catch</code> .  Essayons de consid√©rer la pertinence de ce comportement. </p><br><p>  Supposons que nous ayons une biblioth√®que qui doit cr√©er des threads et impl√©menter une sorte de logique dans ces threads.  En tant qu'utilisateurs de cette biblioth√®que, nous souhaitons uniquement garantir les appels API et recevoir des messages d'erreur.  Si la biblioth√®que plante des flux sans en informer, cela ne peut pas nous aider beaucoup.  De plus, l'effondrement du flux entra√Ænera un message <code>AppDomain.UnhandledException</code> , dans lequel il n'y a aucune information sur le flux particulier qui se trouve de son c√¥t√©.  Si nous parlons de notre code, il est peu probable qu'un flux en panne nous soit utile.  En tout cas, je n'ai pas r√©pondu √† ce besoin.  Notre t√¢che consiste √† traiter correctement les erreurs, √† envoyer des informations sur leur occurrence dans le journal des erreurs et √† terminer correctement le flux.  C'est-√†-dire  envelopper essentiellement la m√©thode avec laquelle le thread d√©marre dans <code>try-catch</code> : </p><br><pre> <code class="plaintext hljs"> ThreadPool.QueueUserWorkitem(_ =&gt; { using(Disposables aggregator = ...){ try { // do work here, plus: aggregator.Add(subscriptions); aggregator.Add(dependantResources); } catch (Exception ex) { logger.Error(ex, "Unhandled exception"); } } });</code> </pre> <br><p>  Dans un tel sch√©ma, nous obtenons ce dont nous avons besoin: d'une part, nous ne briserons pas le flux.  D'autre part, nettoyez correctement les ressources locales si elles ont √©t√© cr√©√©es.  Eh bien, dans l'annexe - nous organisons l'enregistrement de l'erreur re√ßue.  Mais attendez, dites-vous.  D'une mani√®re ou d'une autre, vous avez renomm√© le probl√®me de l'√©v√©nement <code>AppDomain.UnhandledException</code> .  N'est-ce vraiment pas n√©cessaire du tout?  C'est n√©cessaire.  Mais juste pour vous informer que nous avons oubli√© d'envelopper certains threads dans <code>try-catch</code> avec toute la logique n√©cessaire.  Avec tout: avec enregistrement et purification des ressources.  Sinon, ce sera compl√®tement faux: prenez et √©teignez toutes les exceptions, comme si elles n'√©taient pas l√† du tout. </p><br><blockquote><h3>  Lien vers le livre entier </h3><br><ul><li><img src="https://habrastorage.org/webt/3q/6g/qa/3q6gqaz40qx-jzscjf3jbxatxhg.png">  Livre CLR: <a href="https://translate.googleusercontent.com/translate_c?depth=1&amp;rurl=translate.google.com&amp;sl=ru&amp;sp=nmt4&amp;tl=fr&amp;u=">GitHub</a> </li><li><img src="https://habrastorage.org/webt/eo/6g/eo/eo6geog0tg5ernqmv2lcmufefta.png">  Livres de la version 0.5.0, PDF: <a href="">version GitHub</a> </li></ul><br></blockquote><p> <a href="https://translate.googleusercontent.com/translate_c?depth=1&amp;rurl=translate.google.com&amp;sl=ru&amp;sp=nmt4&amp;tl=fr&amp;u="><img src="https://habrastorage.org/getpro/habr/post_images/97f/1d3/cf0/97f1d3cf0e2a6bf007066eb60a789c31.png"></a> </p></div></div><p>Source: <a rel="nofollow" href="https://habr.com/ru/post/fr419929/">https://habr.com/ru/post/fr419929/</a></p>
<section class="more-articles-navigation-panel js-more-articles-navigation-panel">
<h4>More articles:</h4>
<nav class="list-of-articles-container js-list-of-articles-container"><ul class="list-of-pages js-list-of-pages">
<li><a href="../fr419919/index.html">Contr√¥le de version dans SQL Server</a></li>
<li><a href="../fr419921/index.html">Comment supprimer 10 millions de paquets par seconde</a></li>
<li><a href="../fr419923/index.html">Mon travail temporaire, les montres de la carte m√®re</a></li>
<li><a href="../fr419925/index.html">Contr√¥le de version de fichiers individuels √† l'aide de GitHub Gist</a></li>
<li><a href="../fr419927/index.html">[DotNetBook] Exceptions: Type Architecture du syst√®me</a></li>
<li><a href="../fr419931/index.html">[DotNetBook] L'heure des histoires divertissantes: des situations exceptionnellement exceptionnelles</a></li>
<li><a href="../fr419933/index.html">Comment faire des recherches d'utilisateurs sur Github en utilisant Angular</a></li>
<li><a href="../fr419935/index.html">Exactement une fois n'est PAS exactement la m√™me: analyse d'article</a></li>
<li><a href="../fr419939/index.html">Comment j'ai rendu la navigation dans React Native pas si terrible</a></li>
<li><a href="../fr419941/index.html">Visite photo du bureau Audiomania: premi√®re partie</a></li>
</ul></nav>
</section><br />
<a href="../../allArticles.html"><strong>All Articles</strong></a>
<script src="../../js/main.js"></script>

<!-- Yandex.Metrika counter -->
<script type="text/javascript" >
  (function (d, w, c) {
      (w[c] = w[c] || []).push(function() {
          try {
              w.yaCounter57283870 = new Ya.Metrika({
                  id:57283870,
                  clickmap:true,
                  trackLinks:true,
                  accurateTrackBounce:true,
                  webvisor:true
              });
          } catch(e) { }
      });

      var n = d.getElementsByTagName("script")[0],
          s = d.createElement("script"),
          f = function () { n.parentNode.insertBefore(s, n); };
      s.type = "text/javascript";
      s.async = true;
      s.src = "https://mc.yandex.ru/metrika/watch.js";

      if (w.opera == "[object Opera]") {
          d.addEventListener("DOMContentLoaded", f, false);
      } else { f(); }
  })(document, window, "yandex_metrika_callbacks");
</script>
<noscript><div><img src="https://mc.yandex.ru/watch/57283870" style="position:absolute; left:-9999px;" alt="" /></div></noscript>

<!-- Google Analytics -->
  <script>
    window.ga = function () { ga.q.push(arguments) }; ga.q = []; ga.l = +new Date;
    ga('create', 'UA-134228602-6', 'auto'); ga('send', 'pageview')
  </script>
  <script src="https://www.google-analytics.com/analytics.js" async defer></script>

</section>

<footer class="page-footer">
  <div class="page-footer-legal-info-container page-footer-element">
    <p>
      Weekly-Geekly ES | <span class="page-footer-legal-info-year js-page-footer-legal-info-year">2019</span>
    </p>
  </div>
  <div class="page-footer-counters-container page-footer-element">
    <a class="page-footer-counter-clustrmap" href='#'  title='Visit tracker'><img src='https://clustrmaps.com/map_v2.png?cl=698e5a&w=271&t=t&d=9uU9J9pq8z7k8xEBHYSfs6DenIBAHs3vLIHcPIJW9d0&co=3a3a3a&ct=ffffff'/></a>
  </div>
</footer>
  
</body>

</html>