<!doctype html>
<html class="no-js" lang="en">

<head>
  <!-- Global site tag (gtag.js) - Google Analytics -->
  <script async src="https://www.googletagmanager.com/gtag/js?id=UA-134228602-6"></script>
  <script>
    window.dataLayer = window.dataLayer || [];
    function gtag(){dataLayer.push(arguments);}
    gtag('js', new Date());

    gtag('config', 'UA-134228602-6');
  </script>

  <meta charset="utf-8">
  <meta http-equiv="x-ua-compatible" content="ie=edge">
  <title>üîù üë®üèø‚Äçüé® üë©üèª‚ÄçüöÄ [DotNetBook] Eventos de excepci√≥n y c√≥mo obtener StackOverflow y ExecutionEngineException desde cero üßë‚Äçü§ù‚Äçüßë üñçÔ∏è üìÑ</title>
  <link rel="icon" type="image/x-icon" href="/favicon.ico" />
  <meta name="description" content="Eventos de excepci√≥n 


 En el caso general, no siempre conocemos las excepciones que ocurrir√°n en nuestros programas porque casi siempre usamos algo ...">
  <meta name="viewport" content="width=device-width, initial-scale=1, shrink-to-fit=no">

  <link rel="stylesheet" href="../../css/main.css">

  <link href="https://fonts.googleapis.com/css?family=Quicksand&display=swap" rel="stylesheet">

  <script src="https://cdnjs.cloudflare.com/ajax/libs/jquery/3.3.1/jquery.min.js"></script>
  <script>window.jQuery || document.write('<script src="../../js/vendors/jquery-3.3.1.min.js"><\/script>')</script>

  <script>document.write('<script src="//pagea' + 'd2.googles' + 'yndication.com/pagea' + 'd/js/a' + 'dsby' + 'google.js"><\/script>')</script>
  <script>
        var superSpecialObject = {};
        superSpecialObject['google_a' + 'd_client'] = 'ca-p' + 'ub-6974184241884155';
        superSpecialObject['enable_page_level_a' + 'ds'] = true;
       (window['a' + 'dsbygoogle'] = window['a' + 'dsbygoogle'] || []).push(superSpecialObject);
  </script>
</head>

<body>
  <!--[if lte IE 9]>
    <p class="browserupgrade">You are using an <strong>outdated</strong> browser. Please <a href="https://browsehappy.com/">upgrade your browser</a> to improve your experience and security.</p>
  <![endif]-->
  <header class="page-header js-page-header">
    <a class="page-header-logo-container" href="https://weekly-geekly-es.github.io/index.html"></a>
    <div class="page-header-text">Geekly articles weekly</div>
  </header>
  <section class="page js-page"><h1>[DotNetBook] Eventos de excepci√≥n y c√≥mo obtener StackOverflow y ExecutionEngineException desde cero</h1><div class="post__body post__body_full"><div class="post__text post__text-html post__text_v1" id="post-content-body" data-io-article-url="https://habr.com/ru/company/clrium/blog/419929/"><img width="350" src="https://habrastorage.org/webt/vh/7j/tq/vh7jtqhzbne4h3rjhprca2pruhu.png" align="left"><br><h2 id="sobytiya-ob-isklyuchitelnyh-situaciyah">  Eventos de excepci√≥n </h2><br><p> En el caso general, no siempre conocemos las excepciones que ocurrir√°n en nuestros programas porque casi siempre usamos algo escrito por otras personas y que est√° en otros subsistemas y bibliotecas.  No solo puede haber una variedad de situaciones en su propio c√≥digo, en el c√≥digo de otras bibliotecas, tambi√©n hay muchos problemas asociados con la ejecuci√≥n de c√≥digo en dominios aislados.  Y solo en este caso ser√≠a extremadamente √∫til poder recibir datos sobre la operaci√≥n de c√≥digo aislado.  Despu√©s de todo, una situaci√≥n puede ser bastante real cuando el c√≥digo de un tercero intercepta todos los errores sin excepci√≥n, ahogando su <code>fault</code> bloqueo: </p><br><pre> <code class="plaintext hljs">try { // ... } catch { // do nothing, just to make code call more safe }</code> </pre> <br><p>  En tal situaci√≥n, puede resultar que la ejecuci√≥n del c√≥digo ya no sea tan segura como parece, pero no tenemos ning√∫n mensaje sobre ning√∫n problema.  La segunda opci√≥n es cuando la aplicaci√≥n suprime alguna excepci√≥n, incluso legal.  Y el resultado: la siguiente excepci√≥n en un lugar aleatorio har√° que la aplicaci√≥n se bloquee en un futuro debido a un error aparentemente aleatorio.  Aqu√≠ me gustar√≠a tener una idea de los antecedentes de este error.  ¬øCu√°l es el curso de los acontecimientos condujo a esta situaci√≥n?  Y una forma de hacer esto posible es usar eventos adicionales relacionados con situaciones excepcionales: <code>AppDomain.FirstChanceException</code> y <code>AppDomain.UnhandledException</code> . </p><br><blockquote><h3>  Nota </h3><br>  El cap√≠tulo publicado en Habr√© no est√° actualizado y, probablemente, est√° un poco desactualizado.  Y, por lo tanto, consulte el original para obtener un texto m√°s reciente: <br><br><ul><li><img src="https://habrastorage.org/webt/3q/6g/qa/3q6gqaz40qx-jzscjf3jbxatxhg.png">  Libro CLR: <a href="https://translate.googleusercontent.com/translate_c?depth=1&amp;rurl=translate.google.com&amp;sl=ru&amp;sp=nmt4&amp;tl=es&amp;u=">GitHub, tabla de contenido</a> </li><li><img src="https://habrastorage.org/webt/3q/6g/qa/3q6gqaz40qx-jzscjf3jbxatxhg.png">  Libro CLR: <a href="">GitHub, cap√≠tulo</a> </li><li><img src="https://habrastorage.org/webt/eo/6g/eo/eo6geog0tg5ernqmv2lcmufefta.png">  Libros de la versi√≥n 0.5.2, PDF: <a href="">versi√≥n de GitHub</a> </li></ul><br></blockquote><p> <a href="https://translate.googleusercontent.com/translate_c?depth=1&amp;rurl=translate.google.com&amp;sl=ru&amp;sp=nmt4&amp;tl=es&amp;u="><img src="https://habrastorage.org/getpro/habr/post_images/97f/1d3/cf0/97f1d3cf0e2a6bf007066eb60a789c31.png"></a> </p><a name="habracut"></a><br><p>  De hecho, cuando "lanza una excepci√≥n", se llama al m√©todo habitual de alg√∫n subsistema <code>Throw</code> interno, que en su interior realiza las siguientes operaciones: </p><br><ul><li>  Lanza <code>AppDomain.FirstChanceException</code> </li><li>  Busca filtros coincidentes en la cadena de controladores </li><li>  Hace que el controlador pre-ruede la pila al marco deseado. </li><li>  Si no se encuentra ning√∫n controlador, se <code>AppDomain.UnhandledException</code> una <code>AppDomain.UnhandledException</code> , que bloquea el hilo en el que se produjo la excepci√≥n. </li></ul><br><p>  Uno debe hacer una reserva inmediatamente al responder una pregunta que atorment√≥ a muchas mentes: ¬øes posible cancelar de alguna manera la excepci√≥n que ocurri√≥ en el c√≥digo no controlado que se ejecuta en el dominio aislado sin romper el hilo en el que se lanz√≥ esta excepci√≥n?  La respuesta es concisa y simple: no.  Si no se detecta una excepci√≥n en toda la gama de m√©todos llamados, no se puede manejar en principio.  De lo contrario, surge una situaci√≥n extra√±a: si usamos un <code>AppDomain.FirstChanceException</code> manejar (alg√∫n tipo de <code>catch</code> sint√©tica) excepci√≥n, entonces ¬øa qu√© marco deber√≠a volver la pila de hilos?  ¬øC√≥mo configurar esto como parte de las reglas de .NET CLR?  De ninguna manera  Simplemente no es posible.  Lo √∫nico que podemos hacer es registrar la informaci√≥n recibida para futuras investigaciones. </p><br><p>  La segunda cosa para hablar sobre "en tierra" es por qu√© estos eventos se introdujeron no en <code>Thread</code> , sino en <code>AppDomain</code> .  Despu√©s de todo, si sigue la l√≥gica, ¬ød√≥nde surgen excepciones?  En el flujo de ejecuci√≥n del comando.  Es decir  En realidad <code>Thread</code> .  Entonces, ¬øpor qu√© el dominio tiene problemas?  La respuesta es muy simple: ¬øpara qu√© situaciones se <code>AppDomain.UnhandledException</code> <code>AppDomain.FirstChanceException</code> y <code>AppDomain.UnhandledException</code> ?  Entre otras cosas, para crear cajas de arena para complementos.  Es decir  para situaciones en las que hay un determinado <code>AppDomain</code> configurado para PartialTrust.  Cualquier cosa puede suceder dentro de este AppDomain: los subprocesos se pueden crear all√≠ en cualquier momento, o se pueden usar los existentes de ThreadPool.  Entonces resulta que nosotros, estando fuera de este proceso (no escribimos ese c√≥digo), no podemos suscribirnos a los eventos de flujos internos.  Simplemente porque no tenemos idea de qu√© flujos se crearon all√≠.  Pero tenemos la garant√≠a de tener un <code>AppDomain</code> que organiza el sandbox y el enlace al que tenemos. </p><br><p>  Entonces, de hecho, contamos con dos eventos regionales: sucedi√≥ algo que no se supon√≠a ( <code>FirstChanceExecption</code> ) y "todo est√° mal", nadie manej√≥ la excepci√≥n: no se proporcion√≥.  Por lo tanto, el flujo de ejecuci√≥n del comando no tiene sentido y se enviar√° ( <code>Thread</code> ). </p><br><p>  ¬øQu√© se puede obtener al tener estos eventos y por qu√© es malo que los desarrolladores eviten estos eventos? </p><br><h3 id="appdomainfirstchanceexception">  AppDomain.FirstChanceException </h3><br><p>  Este evento es de naturaleza puramente informativa y no puede ser "procesado".  Su tarea es notificarle que se ha producido una excepci√≥n dentro de este dominio y que el c√≥digo de la aplicaci√≥n comenzar√° a procesarlo despu√©s de procesar el evento.  Su ejecuci√≥n conlleva un par de caracter√≠sticas que deben recordarse durante el dise√±o del procesador. </p><br><p>  Pero primero veamos un ejemplo sint√©tico simple de su procesamiento: </p><br><pre> <code class="plaintext hljs">void Main() { var counter = 0; AppDomain.CurrentDomain.FirstChanceException += (_, args) =&gt; { Console.WriteLine(args.Exception.Message); if(++counter == 1) { throw new ArgumentOutOfRangeException(); } }; throw new Exception("Hello!"); }</code> </pre> <br><p>  ¬øQu√© tiene de notable este c√≥digo?  Donde sea que un c√≥digo arroje una excepci√≥n, lo primero que sucede es registrarlo en la consola.  Es decir  incluso si olvida o no puede imaginar el manejo de alg√∫n tipo de excepci√≥n, seguir√° apareciendo en el registro de eventos que est√° organizando.  El segundo es una condici√≥n algo extra√±a para lanzar una excepci√≥n interna.  La <code>FirstChanceException</code> es que dentro del controlador <code>FirstChanceException</code> no puede lanzar y lanzar una excepci√≥n m√°s.  M√°s bien, incluso esto: dentro del controlador FirstChanceException, <em>no puede</em> lanzar al menos ninguna excepci√≥n.  Si lo hace, hay dos posibles eventos.  En el primero, si no <code>if(++counter == 1)</code> condici√≥n <code>if(++counter == 1)</code> , obtendr√≠amos una <code>FirstChanceException</code> infinita para una <code>ArgumentOutOfRangeException</code> nueva.  ¬øQu√© significa esto?  Esto significa que en cierta etapa obtendr√≠amos una <code>StackOverflowException</code> : <code>throw new Exception("Hello!")</code> <code>FirstChanceException</code> m√©todo CLR Throw, que arroja <code>FirstChanceException</code> , que arroja <code>Throw</code> ya para <code>ArgumentOutOfRangeException</code> y luego vuelve a aparecer.  La segunda opci√≥n: nos defendimos por la profundidad de la recursi√≥n utilizando la condici√≥n de <code>counter</code> .  Es decir  en este caso, lanzamos una excepci√≥n solo una vez.  El resultado es m√°s que inesperado: obtenemos una excepci√≥n que realmente funciona dentro de la instrucci√≥n <code>Throw</code> .  ¬øY qu√© es lo m√°s adecuado para este tipo de error?  De acuerdo con ECMA-335, si se arroj√≥ una instrucci√≥n a una excepci√≥n, se debe lanzar una <code>ExecutionEngineException</code> .  Pero no podemos manejar esta situaci√≥n excepcional.  Conduce a un bloqueo completo de la aplicaci√≥n.  ¬øCu√°les son las opciones de procesamiento seguro que tenemos? </p><br><p>  Lo primero que viene a la mente es establecer un bloque <code>try-catch</code> en todo el c√≥digo del controlador <code>FirstChanceException</code> : </p><br><pre> <code class="plaintext hljs">void Main() { var fceStarted = false; var sync = new object(); EventHandler&lt;FirstChanceExceptionEventArgs&gt; handler; handler = new EventHandler&lt;FirstChanceExceptionEventArgs&gt;((_, args) =&gt; { lock (sync) { if (fceStarted) { //     - ,        -      , //   try  . Console.WriteLine($"FirstChanceException inside FirstChanceException ({args.Exception.GetType().FullName})"); return; } fceStarted = true; try { //     . ,   Console.WriteLine(args.Exception.Message); throw new ArgumentOutOfRangeException(); } catch (Exception exception) { //       Console.WriteLine("Success"); } finally { fceStarted = false; } } }); AppDomain.CurrentDomain.FirstChanceException += handler; try { throw new Exception("Hello!"); } finally { AppDomain.CurrentDomain.FirstChanceException -= handler; } } OUTPUT: Hello! Specified argument was out of the range of valid values. FirstChanceException inside FirstChanceException (System.ArgumentOutOfRangeException) Success !Exception: Hello!</code> </pre> <br><p>  Es decir  por un lado, tenemos el c√≥digo para manejar el evento <code>FirstChanceException</code> , y por otro, tenemos c√≥digo adicional para manejar excepciones en el propio <code>FirstChanceException</code> .  Sin embargo, las t√©cnicas de registro para ambas situaciones deber√≠an ser diferentes.  Si el registro de procesamiento de eventos puede ir a su gusto, entonces el procesamiento de errores de l√≥gica de procesamiento de <code>FirstChanceException</code> deber√≠a ir sin excepci√≥n en principio.  La segunda cosa que probablemente not√≥ es la sincronizaci√≥n entre hilos.  Esto puede plantear la pregunta: ¬øpor qu√© est√° aqu√≠ si se produce una excepci√≥n en alg√∫n subproceso, lo que significa que <code>FirstChanceException</code> debe ser seguro para subprocesos.  Sin embargo, no todo es tan alegre.  <code>FirstChanceException</code> que tenemos en AppDomain.  Y esto significa que ocurre para cualquier hilo iniciado en un dominio particular.  Es decir  Si tenemos un dominio dentro del cual se inician varios subprocesos, <code>FirstChanceException</code> puede ir en paralelo.  Y esto significa que necesitamos protegernos de alguna manera con la sincronizaci√≥n: por ejemplo, usando el <code>lock</code> . </p><br><p>  La segunda forma es intentar desviar el procesamiento a un subproceso vecino que pertenece a un dominio de aplicaci√≥n diferente.  Sin embargo, vale la pena mencionar que con tal implementaci√≥n, debemos construir un dominio dedicado espec√≠ficamente para esta tarea para que no funcione y que otros flujos que est√©n funcionando puedan colocar este dominio: </p><br><pre> <code class="plaintext hljs">static void Main() { using (ApplicationLogger.Go(AppDomain.CurrentDomain)) { throw new Exception("Hello!"); } } public class ApplicationLogger : MarshalByRefObject { ConcurrentQueue&lt;Exception&gt; queue = new ConcurrentQueue&lt;Exception&gt;(); CancellationTokenSource cancellation; ManualResetEvent @event; public void LogFCE(Exception message) { queue.Enqueue(message); } private void StartThread() { cancellation = new CancellationTokenSource(); @event = new ManualResetEvent(false); var thread = new Thread(() =&gt; { while (!cancellation.IsCancellationRequested) { if (queue.TryDequeue(out var exception)) { Console.WriteLine(exception.Message); } Thread.Yield(); } @event.Set(); }); thread.Start(); } private void StopAndWait() { cancellation.Cancel(); @event.WaitOne(); } public static IDisposable Go(AppDomain observable) { var dom = AppDomain.CreateDomain("ApplicationLogger", null, new AppDomainSetup { ApplicationBase = AppDomain.CurrentDomain.BaseDirectory, }); var proxy = (ApplicationLogger)dom.CreateInstanceAndUnwrap(typeof(ApplicationLogger).Assembly.FullName, typeof(ApplicationLogger).FullName); proxy.StartThread(); var subscription = new EventHandler&lt;FirstChanceExceptionEventArgs&gt;((_, args) =&gt; { proxy.LogFCE(args.Exception); }); observable.FirstChanceException += subscription; return new Subscription(() =&gt; { observable.FirstChanceException -= subscription; proxy.StopAndWait(); }); } private class Subscription : IDisposable { Action act; public Subscription (Action act) { this.act = act; } public void Dispose() { act(); } } }</code> </pre> <br><p>  En este caso, manejar <code>FirstChanceException</code> es lo m√°s seguro posible: en el hilo vecino que pertenece al dominio vecino.  En este caso, los errores al procesar un mensaje no pueden reducir los flujos de trabajo de la aplicaci√≥n.  Adem√°s, puede escuchar por separado la excepci√≥n UnhandledException del dominio de registro de mensajes: los errores fatales durante el registro no derribar√°n toda la aplicaci√≥n. </p><br><h3 id="appdomainunhandledexception">  AppDomain.UnhandledException </h3><br><p>  El segundo mensaje que podemos atrapar y que trata con el manejo de excepciones es <code>AppDomain.UnhandledException</code> .  Este mensaje es una muy mala noticia para nosotros porque significa que no hab√≠a nadie que pudiera encontrar la manera de manejar el error en un determinado hilo.  Adem√°s, si tal situaci√≥n ha ocurrido, todo lo que podemos hacer es "aclarar" las consecuencias de tal error.  Es decir  de ninguna manera para limpiar los recursos que pertenecen solo a esta secuencia si se cre√≥ alguno.  Sin embargo, una situaci√≥n a√∫n mejor es manejar excepciones mientras est√° en la ra√≠z de los hilos sin bloquear el hilo.  Es decir  esencialmente poner <code>try-catch</code> .  Tratemos de considerar la idoneidad de este comportamiento. </p><br><p>  Supongamos que tenemos una biblioteca que necesita crear hilos e implementar alg√∫n tipo de l√≥gica en estos hilos.  Nosotros, como usuarios de esta biblioteca, solo estamos interesados ‚Äã‚Äãen garantizar llamadas API y en recibir mensajes de error.  Si la biblioteca bloquea las transmisiones sin notificarlo, esto no nos puede ayudar mucho.  Adem√°s, el colapso de la secuencia dar√° lugar a un mensaje <code>AppDomain.UnhandledException</code> , en el que no hay informaci√≥n sobre qu√© secuencia particular se encuentra de su lado.  Si estamos hablando de nuestro c√≥digo, es poco probable que una secuencia que se cuelgue sea √∫til para nosotros.  En cualquier caso, no satisfac√≠a la necesidad de esto.  Nuestra tarea es procesar los errores correctamente, enviar informaci√≥n sobre su aparici√≥n al registro de errores y finalizar correctamente el flujo.  Es decir  esencialmente envolver el m√©todo con el que el hilo comienza en <code>try-catch</code> : </p><br><pre> <code class="plaintext hljs"> ThreadPool.QueueUserWorkitem(_ =&gt; { using(Disposables aggregator = ...){ try { // do work here, plus: aggregator.Add(subscriptions); aggregator.Add(dependantResources); } catch (Exception ex) { logger.Error(ex, "Unhandled exception"); } } });</code> </pre> <br><p>  En tal esquema, obtenemos lo que necesitamos: por un lado, no vamos a romper la corriente.  Por otro lado, limpie correctamente los recursos locales si se crearon.  Bueno, en el ap√©ndice, organizamos el registro del error recibido.  Pero espera, dices.  De alguna manera, rebot√≥ el tema del evento <code>AppDomain.UnhandledException</code> .  ¬øRealmente no es necesario en absoluto?  Es necesario  Pero solo para informar que olvidamos envolver algunos hilos en <code>try-catch</code> con toda la l√≥gica necesaria.  Con todo: con registro y purificaci√≥n de recursos.  De lo contrario, ser√° completamente incorrecto: tomar y extinguir todas las excepciones, como si no estuvieran all√≠. </p><br><blockquote><h3>  Enlace a todo el libro </h3><br><ul><li><img src="https://habrastorage.org/webt/3q/6g/qa/3q6gqaz40qx-jzscjf3jbxatxhg.png">  Libro CLR: <a href="https://translate.googleusercontent.com/translate_c?depth=1&amp;rurl=translate.google.com&amp;sl=ru&amp;sp=nmt4&amp;tl=es&amp;u=">GitHub</a> </li><li><img src="https://habrastorage.org/webt/eo/6g/eo/eo6geog0tg5ernqmv2lcmufefta.png">  Libros de la versi√≥n 0.5.0, PDF: <a href="">versi√≥n de GitHub</a> </li></ul><br></blockquote><p> <a href="https://translate.googleusercontent.com/translate_c?depth=1&amp;rurl=translate.google.com&amp;sl=ru&amp;sp=nmt4&amp;tl=es&amp;u="><img src="https://habrastorage.org/getpro/habr/post_images/97f/1d3/cf0/97f1d3cf0e2a6bf007066eb60a789c31.png"></a> </p></div></div><p>Source: <a rel="nofollow" href="https://habr.com/ru/post/es419929/">https://habr.com/ru/post/es419929/</a></p>
<section class="more-articles-navigation-panel js-more-articles-navigation-panel">
<h4>More articles:</h4>
<nav class="list-of-articles-container js-list-of-articles-container"><ul class="list-of-pages js-list-of-pages">
<li><a href="../es419919/index.html">Control de versiones dentro de SQL Server</a></li>
<li><a href="../es419921/index.html">C√≥mo soltar 10 millones de paquetes por segundo</a></li>
<li><a href="../es419923/index.html">Mi trabajo temporal, relojes de placa base</a></li>
<li><a href="../es419925/index.html">Control de versiones de archivos individuales usando GitHub Gist</a></li>
<li><a href="../es419927/index.html">[DotNetBook] Excepciones: Arquitectura de sistema de tipo</a></li>
<li><a href="../es419931/index.html">[DotNetBook] Tiempo para historias entretenidas: situaciones excepcionalmente excepcionales</a></li>
<li><a href="../es419933/index.html">C√≥mo hacer b√∫squedas de usuarios en Github usando Angular</a></li>
<li><a href="../es419935/index.html">Exactamente una vez NO es exactamente lo mismo: an√°lisis de art√≠culos</a></li>
<li><a href="../es419939/index.html">C√≥mo hice que la navegaci√≥n en React Native no sea tan terrible</a></li>
<li><a href="../es419941/index.html">Recorrido fotogr√°fico por la oficina de Audiomania: primera parte</a></li>
</ul></nav>
</section><br />
<a href="../../allArticles.html"><strong>All Articles</strong></a>
<script src="../../js/main.js"></script>

<!-- Yandex.Metrika counter -->
<script type="text/javascript" >
  (function (d, w, c) {
      (w[c] = w[c] || []).push(function() {
          try {
              w.yaCounter57283870 = new Ya.Metrika({
                  id:57283870,
                  clickmap:true,
                  trackLinks:true,
                  accurateTrackBounce:true,
                  webvisor:true
              });
          } catch(e) { }
      });

      var n = d.getElementsByTagName("script")[0],
          s = d.createElement("script"),
          f = function () { n.parentNode.insertBefore(s, n); };
      s.type = "text/javascript";
      s.async = true;
      s.src = "https://mc.yandex.ru/metrika/watch.js";

      if (w.opera == "[object Opera]") {
          d.addEventListener("DOMContentLoaded", f, false);
      } else { f(); }
  })(document, window, "yandex_metrika_callbacks");
</script>
<noscript><div><img src="https://mc.yandex.ru/watch/57283870" style="position:absolute; left:-9999px;" alt="" /></div></noscript>

<!-- Google Analytics -->
  <script>
    window.ga = function () { ga.q.push(arguments) }; ga.q = []; ga.l = +new Date;
    ga('create', 'UA-134228602-6', 'auto'); ga('send', 'pageview')
  </script>
  <script src="https://www.google-analytics.com/analytics.js" async defer></script>

</section>

<footer class="page-footer">
  <div class="page-footer-legal-info-container page-footer-element">
    <p>
      Weekly-Geekly ES | <span class="page-footer-legal-info-year js-page-footer-legal-info-year">2019</span>
    </p>
  </div>
  <div class="page-footer-counters-container page-footer-element">
    <a class="page-footer-counter-clustrmap" href='#'  title='Visit tracker'><img src='https://clustrmaps.com/map_v2.png?cl=698e5a&w=271&t=t&d=9uU9J9pq8z7k8xEBHYSfs6DenIBAHs3vLIHcPIJW9d0&co=3a3a3a&ct=ffffff'/></a>
  </div>
</footer>
  
</body>

</html>