<!doctype html>
<html class="no-js" lang="en">

<head>
  <!-- Global site tag (gtag.js) - Google Analytics -->
  <script async src="https://www.googletagmanager.com/gtag/js?id=UA-134228602-6"></script>
  <script>
    window.dataLayer = window.dataLayer || [];
    function gtag(){dataLayer.push(arguments);}
    gtag('js', new Date());

    gtag('config', 'UA-134228602-6');
  </script>

  <meta charset="utf-8">
  <meta http-equiv="x-ua-compatible" content="ie=edge">
  <title>🚴🏻 🥢 👘 Pengecualian yang menghancurkan 🚨 🧜 👩🏻‍💼</title>
  <link rel="icon" type="image/x-icon" href="/favicon.ico" />
  <meta name="description" content="Sekali lagi tentang mengapa membuang pengecualian pada destruktor itu buruk 


 Banyak pakar C ++ (misalnya, Herb Sutter ) mengajarkan kepada kita bah...">
  <meta name="viewport" content="width=device-width, initial-scale=1, shrink-to-fit=no">

  <link rel="stylesheet" href="../../css/main.css">

  <link href="https://fonts.googleapis.com/css?family=Quicksand&display=swap" rel="stylesheet">

  <script src="https://cdnjs.cloudflare.com/ajax/libs/jquery/3.3.1/jquery.min.js"></script>
  <script>window.jQuery || document.write('<script src="../../js/vendors/jquery-3.3.1.min.js"><\/script>')</script>

  <script>document.write('<script src="//pagea' + 'd2.googles' + 'yndication.com/pagea' + 'd/js/a' + 'dsby' + 'google.js"><\/script>')</script>
  <script>
        var superSpecialObject = {};
        superSpecialObject['google_a' + 'd_client'] = 'ca-p' + 'ub-6974184241884155';
        superSpecialObject['enable_page_level_a' + 'ds'] = true;
       (window['a' + 'dsbygoogle'] = window['a' + 'dsbygoogle'] || []).push(superSpecialObject);
  </script>
</head>

<body>
  <!--[if lte IE 9]>
    <p class="browserupgrade">You are using an <strong>outdated</strong> browser. Please <a href="https://browsehappy.com/">upgrade your browser</a> to improve your experience and security.</p>
  <![endif]-->
  <header class="page-header js-page-header">
    <a class="page-header-logo-container" href="https://weekly-geekly-es.github.io/index.html"></a>
    <div class="page-header-text">Geekly articles weekly</div>
  </header>
  <section class="page js-page"><h1>Pengecualian yang menghancurkan</h1><div class="post__body post__body_full"><div class="post__text post__text-html post__text_v1" id="post-content-body" data-io-article-url="https://habr.com/ru/post/433944/"><h2 id="eschyo-raz-o-tom-pochemu-ploho-brosat-isklyucheniya-v-destruktorah">  Sekali lagi tentang mengapa membuang pengecualian pada destruktor itu buruk </h2><br><p>  Banyak pakar C ++ (misalnya, <a href="https://translate.googleusercontent.com/translate_c?depth=1&amp;rurl=translate.google.com&amp;sl=ru&amp;sp=nmt4&amp;tl=id&amp;u=">Herb Sutter</a> ) mengajarkan kepada kita bahwa melemparkan pengecualian pada destruktor adalah buruk, karena Anda dapat masuk ke destruktor selama promosi tumpukan dengan pengecualian yang sudah dilemparkan, dan jika pengecualian lain dilemparkan pada titik ini, <em>std</em> akan dipanggil <em>:: terminate ()</em> .  Standar bahasa C ++ 17 (selanjutnya saya merujuk pada versi draft <a href="https://translate.googleusercontent.com/translate_c?depth=1&amp;rurl=translate.google.com&amp;sl=ru&amp;sp=nmt4&amp;tl=id&amp;u=">N4713 yang</a> tersedia bebas) tentang topik ini memberi tahu kita hal berikut: </p><a name="habracut"></a><br><blockquote>  <strong>18.5.1 Fungsi std :: terminate () [exception.terminate]</strong> <br><br>  1 Dalam beberapa situasi, penanganan pengecualian harus ditinggalkan untuk teknik penanganan kesalahan yang kurang halus.  [Catatan: <br><br>  Situasi-situasi ini adalah: <br><br>  ... <br><br>  (1.4) ketika penghancuran objek selama tumpukan unwinding (18.2) berakhir dengan melemparkan pengecualian, atau <br><br>  ... <br><br>  - catatan akhir] </blockquote><p>  Mari kita periksa contoh sederhana: </p><br><pre><code class="plaintext hljs">#include &lt;iostream&gt; class PrintInDestructor { public: ~PrintInDestructor() noexcept { std::cerr &lt;&lt; "~PrintInDestructor() invoked\n"; } }; void throw_int_func() { std::cerr &lt;&lt; "throw_int_func() invoked\n"; throw 1; } class ThrowInDestructor { public: ~ThrowInDestructor() noexcept(false) { std::cerr &lt;&lt; "~ThrowInDestructor() invoked\n"; throw_int_func(); } private: PrintInDestructor member_; }; int main(int, char**) { try { ThrowInDestructor bad; throw "BANG!"; } catch (int i) { std::cerr &lt;&lt; "Catched int exception: " &lt;&lt; i &lt;&lt; "\n"; } catch (const char* c) { std::cerr &lt;&lt; "Catched const char* exception: " &lt;&lt; c &lt;&lt; "\n"; } catch (...) { std::cerr &lt;&lt; "Catched unknown exception\n"; } return 0; }</code> </pre> <br><p>  Hasil: </p><br><pre> <code class="plaintext hljs">~ThrowInDestructor() invoked throw_int_func() invoked ~PrintInDestructor() invoked terminate called after throwing an instance of 'int' Aborted</code> </pre> <br><p>  Perhatikan bahwa destruktor <em>PrintInDestructor</em> masih dipanggil, yaitu  setelah melempar pengecualian kedua, promosi tumpukan tidak terganggu.  Standar (paragraf yang sama 18.5.1) tentang hal ini mengatakan sebagai berikut: </p><br><blockquote>  2 ... Dalam situasi di mana tidak ada pawang yang cocok ditemukan, <br>  itu adalah implementasi yang ditentukan apakah stack dibatalkan atau tidak sebelum std :: terminate () dipanggil.  Masuk <br>  situasi di mana pencarian pawang (18.3) bertemu blok terluar dari fungsi dengan a <br>  spesifikasi pengecualian non-melempar (18.4), itu adalah implementasi-ditentukan apakah stack dibatalkan, <br>  membatalkan sebagian, atau tidak membatalkan sama sekali sebelum std :: terminate () disebut ... </blockquote><p>  Saya menguji contoh ini pada beberapa versi <strong>GCC</strong> (8.2, 7.3) dan <strong>Dentang</strong> (6.0, 5.0), di mana-mana promosi stack berlanjut.  Jika Anda menemukan kompiler di mana implementasi yang didefinisikan berbeda, silakan menulis tentang itu di komentar. </p><br><p>  Juga harus dicatat bahwa <em>std :: terminate ()</em> dipanggil ketika stack dibatalkan hanya ketika pengecualian dilempar keluar dari destructor.  Jika ada blok coba / tangkap di dalam destruktor yang menangkap pengecualian dan tidak melempar lebih jauh, ini tidak mengganggu promosi tumpukan pengecualian eksternal. </p><br><pre> <code class="plaintext hljs">class ThrowCatchInDestructor { public: ~ThrowCatchInDestructor() noexcept(false) { try { throw_int_func(); } catch (int i) { std::cerr &lt;&lt; "Catched int in ~ThrowCatchInDestructor(): " &lt;&lt; i &lt;&lt; "\n"; } } private: PrintInDestructor member_; }; int main(int, char**) { try { ThrowCatchInDestructor good; std::cerr &lt;&lt; "ThrowCatchInDestructor instance created\n"; throw "BANG!"; } catch (int i) { std::cerr &lt;&lt; "Catched int exception: " &lt;&lt; i &lt;&lt; "\n"; } catch (const char* s) { std::cerr &lt;&lt; "Catched const char* exception: " &lt;&lt; s &lt;&lt; "\n"; } catch (...) { std::cerr &lt;&lt; "Catched unknown exception\n"; } return 0; }</code> </pre> <br><p>  menampilkan </p><br><pre> <code class="plaintext hljs">ThrowCatchInDestructor instance created throw_int_func() invoked Catched int in ~ThrowCatchInDestructor(): 1 ~PrintInDestructor() invoked Catched const char* exception: BANG!</code> </pre> <br><p>  Bagaimana cara menghindari situasi yang tidak menyenangkan?  Secara teori, semuanya sederhana: jangan pernah melempar pengecualian pada destruktor.  Namun, dalam praktiknya tidak begitu sederhana untuk dengan indah dan elegan mewujudkan persyaratan sederhana ini. </p><br><h2 id="esli-nelzya-no-ochen-hochetsya">  Jika Anda tidak bisa, tetapi benar-benar ingin ... </h2><br><blockquote>  Saya akan segera mencatat bahwa saya tidak berusaha membenarkan melemparkan pengecualian dari destruktor, dan mengikuti Sutter, Meyers, dan guru C ++ lainnya, saya mendorong Anda <strong>untuk mencoba</strong> tidak pernah melakukan ini (setidaknya dalam kode baru).  Namun demikian, dalam praktik nyata, seorang programmer mungkin menemukan kode warisan, yang tidak begitu mudah mengarah pada standar tinggi.  Selain itu, teknik yang sering dijelaskan di bawah ini dapat berguna selama proses debugging. </blockquote><p>  Sebagai contoh, kami sedang mengembangkan perpustakaan dengan kelas wrapper yang merangkum kerja dengan sumber daya tertentu.  Sesuai dengan prinsip-prinsip RAII, kami mengambil sumber daya di konstruktor dan harus membebaskannya di destruktor.  Tetapi bagaimana jika upaya untuk membebaskan sumber daya gagal?  Opsi untuk mengatasi masalah ini: </p><br><ul><li>  Abaikan kesalahannya.  Buruk, karena kami menyembunyikan masalah yang dapat mempengaruhi bagian lain dari sistem. </li><li>  Tulis ke log.  Lebih baik daripada hanya mengabaikannya, tapi tetap saja buruk, karena  perpustakaan kami tidak tahu apa-apa tentang kebijakan logging yang diadopsi dalam sistem yang menggunakannya.  Log standar dapat dialihkan ke / dev / null, akibatnya, sekali lagi, kita tidak akan melihat kesalahan. </li><li>  Ambil pelepasan sumber daya ke fungsi terpisah yang mengembalikan nilai atau melempar pengecualian, dan memaksa pengguna kelas untuk menyebutnya sendiri.  Itu buruk, karena pengguna bisa lupa melakukan ini sama sekali, dan kami akan menerima kebocoran sumber daya. </li><li>  Lempar pengecualian.  Bagus dalam kasus biasa, seperti  pengguna kelas dapat menangkap pengecualian dan mendapatkan informasi tentang kesalahan dengan cara standar.  Buruk selama promosi tumpukan, sebagai  mengarah ke <em>std :: terminate ()</em> . </li></ul><br><p>  Bagaimana memahami apakah kita sedang dalam proses mempromosikan tumpukan dengan pengecualian atau tidak?  Di C ++, ada fungsi khusus <em>std :: uncaught_exception () untuk ini</em> .  Dengan bantuannya, kita dapat dengan aman melempar pengecualian dalam situasi normal, atau melakukan sesuatu yang kurang benar, tetapi tidak mengarah pada melemparkan pengecualian selama promosi tumpukan. </p><br><pre> <code class="plaintext hljs">class ThrowInDestructor { public: ~ThrowInDestructor() noexcept(false) { if (std::uncaught_exception()) { std::cerr &lt;&lt; "~ThrowInDestructor() stack unwinding, not throwing\n"; } else { std::cerr &lt;&lt; "~ThrowInDestructor() normal case, throwing\n"; throw_int_func(); } } private: PrintInDestructor member_; }; int main(int, char**) { try { ThrowInDestructor normal; std::cerr &lt;&lt; "ThrowInDestructor normal destruction\n"; } catch (int i) { std::cerr &lt;&lt; "Catched int exception: " &lt;&lt; i &lt;&lt; "\n"; } try { ThrowInDestructor stack_unwind; std::cerr &lt;&lt; "ThrowInDestructor stack unwinding\n"; throw "BANG!"; } catch (int i) { std::cerr &lt;&lt; "Catched int exception: " &lt;&lt; i &lt;&lt; "\n"; } catch (const char* s) { std::cerr &lt;&lt; "Catched const char* exception: " &lt;&lt; s &lt;&lt; "\n"; } catch (...) { std::cerr &lt;&lt; "Catched unknown exception\n"; } return 0; }</code> </pre> <br><p>  Hasil: </p><br><pre> <code class="plaintext hljs">ThrowInDestructor normal destruction ~ThrowInDestructor() normal case, throwing throw_int_func() invoked ~PrintInDestructor() invoked Catched int exception: 1 ThrowInDestructor stack unwinding ~ThrowInDestructor() stack unwinding, not throwing ~PrintInDestructor() invoked Catched const char* exception: BANG!</code> </pre> <br><p>  Perhatikan bahwa fungsi <em>std :: uncaught_exception ()</em> sudah <em>tidak digunakan lagi</em> sejak C ++ Standard 17, oleh karena itu, untuk mengkompilasi contoh, vorning yang sesuai harus ditekan (lihat <a href="https://translate.googleusercontent.com/translate_c?depth=1&amp;rurl=translate.google.com&amp;sl=ru&amp;sp=nmt4&amp;tl=id&amp;u=">repositori dengan contoh-contoh dari artikel</a> ). </p><br><p>  Masalah dengan fungsi ini adalah ia memeriksa apakah kita sedang dalam proses memutar stack dengan pengecualian.  Tetapi tidak mungkin untuk memahami jika destructor saat ini dipanggil selama proses promosi tumpukan.  Akibatnya, jika ada promosi tumpukan, tetapi destruktor dari beberapa objek disebut normal, <em>std :: uncaught_exception ()</em> masih akan mengembalikan <em>true</em> . </p><br><pre> <code class="plaintext hljs">class MayThrowInDestructor { public: ~MayThrowInDestructor() noexcept(false) { if (std::uncaught_exception()) { std::cerr &lt;&lt; "~MayThrowInDestructor() stack unwinding, not throwing\n"; } else { std::cerr &lt;&lt; "~MayThrowInDestructor() normal case, throwing\n"; throw_int_func(); } } }; class ThrowCatchInDestructor { public: ~ThrowCatchInDestructor() noexcept(false) { try { MayThrowInDestructor may_throw; } catch (int i) { std::cerr &lt;&lt; "Catched int in ~ThrowCatchInDestructor(): " &lt;&lt; i &lt;&lt; "\n"; } } private: PrintInDestructor member_; }; int main(int, char**) { try { ThrowCatchInDestructor stack_unwind; std::cerr &lt;&lt; "ThrowInDestructor stack unwinding\n"; throw "BANG!"; } catch (int i) { std::cerr &lt;&lt; "Catched int exception: " &lt;&lt; i &lt;&lt; "\n"; } catch (const char* s) { std::cerr &lt;&lt; "Catched const char* exception: " &lt;&lt; s &lt;&lt; "\n"; } catch (...) { std::cerr &lt;&lt; "Catched unknown exception\n"; } return 0; }</code> </pre> <br><p>  Hasil: </p><br><pre> <code class="plaintext hljs">ThrowInDestructor stack unwinding ~MayThrowInDestructor() stack unwinding, not throwing ~PrintInDestructor() invoked Catched const char* exception: BANG!</code> </pre> <br><p>  Dalam Standar C ++ 17 yang baru, fungsi <em>std :: uncaught_exceptions ()</em> diperkenalkan untuk menggantikan <em>std :: uncaught_exception ()</em> (perhatikan bentuk jamak), yang alih-alih nilai Boolean mengembalikan jumlah pengecualian yang saat ini aktif (di sini adalah <a href="https://translate.googleusercontent.com/translate_c?depth=1&amp;rurl=translate.google.com&amp;sl=ru&amp;sp=nmt4&amp;tl=id&amp;u=">justifikasi</a> terperinci). </p><br><p>  Ini adalah bagaimana masalah yang dijelaskan di atas diselesaikan dengan <em>std :: uncaught_exceptions ()</em> : </p><br><pre> <code class="plaintext hljs">class MayThrowInDestructor { public: MayThrowInDestructor() : exceptions_(std::uncaught_exceptions()) {} ~MayThrowInDestructor() noexcept(false) { if (std::uncaught_exceptions() &gt; exceptions_) { std::cerr &lt;&lt; "~MayThrowInDestructor() stack unwinding, not throwing\n"; } else { std::cerr &lt;&lt; "~MayThrowInDestructor() normal case, throwing\n"; throw_int_func(); } } private: int exceptions_; }; class ThrowCatchInDestructor { public: ~ThrowCatchInDestructor() noexcept(false) { try { MayThrowInDestructor may_throw; } catch (int i) { std::cerr &lt;&lt; "Catched int in ~ThrowCatchInDestructor(): " &lt;&lt; i &lt;&lt; "\n"; } } private: PrintInDestructor member_; }; int main(int, char**) { try { ThrowCatchInDestructor stack_unwind; std::cerr &lt;&lt; "ThrowInDestructor stack unwinding\n"; throw "BANG!"; } catch (int i) { std::cerr &lt;&lt; "Catched int exception: " &lt;&lt; i &lt;&lt; "\n"; } catch (const char* s) { std::cerr &lt;&lt; "Catched const char* exception: " &lt;&lt; s &lt;&lt; "\n"; } catch (...) { std::cerr &lt;&lt; "Catched unknown exception\n"; } return 0; }</code> </pre> <br><p>  Hasil: </p><br><pre> <code class="plaintext hljs">ThrowInDestructor stack unwinding ~MayThrowInDestructor() normal case, throwing throw_int_func() invoked Catched int in ~ThrowCatchInDestructor(): 1 ~PrintInDestructor() invoked Catched const char* exception: BANG!</code> </pre> <br><h2 id="kogda-ochen-ochen-hochetsya-vybrosit-srazu-neskolko-isklyucheniy">  Ketika saya benar-benar ingin sekali melemparkan beberapa pengecualian sekaligus </h2><br><p>  <em>std :: uncaught_exceptions ()</em> menghindari memanggil <em>std :: terminate ()</em> , tetapi tidak membantu menangani beberapa pengecualian dengan benar.  Idealnya, saya ingin memiliki mekanisme yang memungkinkan saya untuk menyimpan semua pengecualian yang dilemparkan, dan kemudian memprosesnya di satu tempat. </p><br><blockquote>  Saya ingin mengingatkan sekali lagi bahwa mekanisme yang diusulkan oleh saya di bawah ini hanya berfungsi untuk menunjukkan konsep dan tidak direkomendasikan untuk digunakan dalam kode industri nyata. </blockquote><p>  Inti dari idenya adalah menangkap pengecualian dan menyimpannya dalam wadah, lalu mendapatkan dan memprosesnya satu per satu.  Untuk menyimpan objek pengecualian, C ++ memiliki tipe khusus <em>std :: exception_ptr</em> .  Tipe struktur dalam Standar tidak diungkapkan, tetapi dikatakan bahwa itu pada dasarnya <em>shared_ptr</em> per objek pengecualian. </p><br><p>  Lalu bagaimana memproses pengecualian ini?  Ada fungsi <em>std :: rethrow_exception () untuk ini</em> , yang mengambil pointer <em>std :: exception_ptr</em> dan melempar pengecualian yang sesuai.  Kita hanya perlu menangkapnya dengan bagian tangkapan yang sesuai dan memprosesnya, setelah itu kita bisa beralih ke objek pengecualian berikutnya. </p><br><pre> <code class="plaintext hljs">using exceptions_queue = std::stack&lt;std::exception_ptr&gt;; // Get exceptions queue for current thread exceptions_queue&amp; get_queue() { thread_local exceptions_queue queue_; return queue_; } // Invoke functor and save exception in queue void safe_invoke(std::function&lt;void()&gt; f) noexcept { try { f(); } catch (...) { get_queue().push(std::current_exception()); } } class ThrowInDestructor { public: ~ThrowInDestructor() noexcept { std::cerr &lt;&lt; "~ThrowInDestructor() invoked\n"; safe_invoke([]() { throw_int_func(); }); } private: PrintInDestructor member_; }; int main(int, char**) { safe_invoke([]() { ThrowInDestructor bad; throw "BANG!"; }); auto&amp; q = get_queue(); while (!q.empty()) { try { std::exception_ptr ex = q.top(); q.pop(); if (ex != nullptr) { std::rethrow_exception(ex); } } catch (int i) { std::cerr &lt;&lt; "Catched int exception: " &lt;&lt; i &lt;&lt; "\n"; } catch (const char* s) { std::cerr &lt;&lt; "Catched const char* exception: " &lt;&lt; s &lt;&lt; "\n"; } catch (...) { std::cerr &lt;&lt; "Catched unknown exception\n"; } } return 0; }</code> </pre> <br><p>  Hasil: </p><br><pre> <code class="plaintext hljs">~ThrowInDestructor() invoked throw_int_func() invoked ~PrintInDestructor() invoked Catched const char* exception: BANG! Catched int exception: 1</code> </pre> <br><p>  Dalam contoh di atas, tumpukan digunakan untuk menyimpan objek pengecualian, namun penanganan pengecualian akan dilakukan sesuai dengan prinsip FIFO (yaitu, secara logis ini adalah antrian - pengecualian yang dilempar terlebih dahulu akan menjadi yang pertama diproses). </p><br><h2 id="vyvody">  Kesimpulan </h2><br><p>  Melontarkan pengecualian pada destruktor objek benar-benar ide yang buruk, dan dalam kode baru apa pun saya sangat menyarankan untuk tidak melakukan ini dengan mendeklarasikan destruktor <em>noexcept</em> .  Namun, dengan dukungan dan debugging kode lama, mungkin ada kebutuhan untuk menangani pengecualian yang dilemparkan dari destruktor, termasuk selama promosi stack, dan C ++ modern memberi kita mekanisme untuk ini.  Saya harap ide-ide yang disajikan dalam artikel ini akan membantu Anda di sepanjang jalan yang sulit ini. </p><br><h2 id="ssylki">  Referensi </h2><br><p>  <a href="https://translate.googleusercontent.com/translate_c?depth=1&amp;rurl=translate.google.com&amp;sl=ru&amp;sp=nmt4&amp;tl=id&amp;u=">Repositori dengan contoh-contoh dari artikel</a> </p></div></div><p>Source: <a rel="nofollow" href="https://habr.com/ru/post/id433944/">https://habr.com/ru/post/id433944/</a></p>
<section class="more-articles-navigation-panel js-more-articles-navigation-panel">
<h4>More articles:</h4>
<nav class="list-of-articles-container js-list-of-articles-container"><ul class="list-of-pages js-list-of-pages">
<li><a href="../id433932/index.html">Kami menembak di kaki, memproses data input</a></li>
<li><a href="../id433934/index.html">SAFe atau Scaled Agile Framework</a></li>
<li><a href="../id433936/index.html">Mencari hadiah teknologi tinggi untuk anak? Pikirkan taman bermain, bukan playpen</a></li>
<li><a href="../id433938/index.html">Bagaimana Yandex dan Google merangkum tahun ini</a></li>
<li><a href="../id433940/index.html">Berapa Ulasan di AppStore</a></li>
<li><a href="../id433946/index.html">Cheat sheet untuk kecerdasan buatan - buang kelebihannya, ajarkan hal utama. Pelatihan teknik pemrosesan urutan</a></li>
<li><a href="../id433948/index.html">Cara membuat pembayaran lebih nyaman: pengalaman penyedia IaaS</a></li>
<li><a href="../id433952/index.html">10 alasan untuk memilih solusi untuk SAP HANA dari HPE. Bagian 2</a></li>
<li><a href="../id433954/index.html">Delapan teknologi audio dan gadget audio yang akan memasuki TECnology Hall of Fame pada tahun 2019</a></li>
<li><a href="../id433956/index.html">Modder telah menggunakan AI untuk meningkatkan tekstur dalam game</a></li>
</ul></nav>
</section><br />
<a href="../../allArticles.html"><strong>All Articles</strong></a>
<script src="../../js/main.js"></script>

<!-- Yandex.Metrika counter -->
<script type="text/javascript" >
  (function (d, w, c) {
      (w[c] = w[c] || []).push(function() {
          try {
              w.yaCounter57283870 = new Ya.Metrika({
                  id:57283870,
                  clickmap:true,
                  trackLinks:true,
                  accurateTrackBounce:true,
                  webvisor:true
              });
          } catch(e) { }
      });

      var n = d.getElementsByTagName("script")[0],
          s = d.createElement("script"),
          f = function () { n.parentNode.insertBefore(s, n); };
      s.type = "text/javascript";
      s.async = true;
      s.src = "https://mc.yandex.ru/metrika/watch.js";

      if (w.opera == "[object Opera]") {
          d.addEventListener("DOMContentLoaded", f, false);
      } else { f(); }
  })(document, window, "yandex_metrika_callbacks");
</script>
<noscript><div><img src="https://mc.yandex.ru/watch/57283870" style="position:absolute; left:-9999px;" alt="" /></div></noscript>

<!-- Google Analytics -->
  <script>
    window.ga = function () { ga.q.push(arguments) }; ga.q = []; ga.l = +new Date;
    ga('create', 'UA-134228602-6', 'auto'); ga('send', 'pageview')
  </script>
  <script src="https://www.google-analytics.com/analytics.js" async defer></script>

</section>

<footer class="page-footer">
  <div class="page-footer-legal-info-container page-footer-element">
    <p>
      Weekly-Geekly ES | <span class="page-footer-legal-info-year js-page-footer-legal-info-year">2019</span>
    </p>
  </div>
  <div class="page-footer-counters-container page-footer-element">
    <a class="page-footer-counter-clustrmap" href='#'  title='Visit tracker'><img src='https://clustrmaps.com/map_v2.png?cl=698e5a&w=271&t=t&d=9uU9J9pq8z7k8xEBHYSfs6DenIBAHs3vLIHcPIJW9d0&co=3a3a3a&ct=ffffff'/></a>
  </div>
</footer>
  
</body>

</html>