<!doctype html>
<html class="no-js" lang="en">

<head>
  <!-- Global site tag (gtag.js) - Google Analytics -->
  <script async src="https://www.googletagmanager.com/gtag/js?id=UA-134228602-6"></script>
  <script>
    window.dataLayer = window.dataLayer || [];
    function gtag(){dataLayer.push(arguments);}
    gtag('js', new Date());

    gtag('config', 'UA-134228602-6');
  </script>

  <meta charset="utf-8">
  <meta http-equiv="x-ua-compatible" content="ie=edge">
  <title>üîî üòå üëô Excepciones devastadoras ‚ò¢Ô∏è üõçÔ∏è üî¨</title>
  <link rel="icon" type="image/x-icon" href="/favicon.ico" />
  <meta name="description" content="Una vez m√°s sobre por qu√© es malo lanzar excepciones en destructores 


 Muchos expertos en C ++ (por ejemplo, Herb Sutter ) nos ense√±an que lanzar ex...">
  <meta name="viewport" content="width=device-width, initial-scale=1, shrink-to-fit=no">

  <link rel="stylesheet" href="../../css/main.css">

  <link href="https://fonts.googleapis.com/css?family=Quicksand&display=swap" rel="stylesheet">

  <script src="https://cdnjs.cloudflare.com/ajax/libs/jquery/3.3.1/jquery.min.js"></script>
  <script>window.jQuery || document.write('<script src="../../js/vendors/jquery-3.3.1.min.js"><\/script>')</script>

  <script>document.write('<script src="//pagea' + 'd2.googles' + 'yndication.com/pagea' + 'd/js/a' + 'dsby' + 'google.js"><\/script>')</script>
  <script>
        var superSpecialObject = {};
        superSpecialObject['google_a' + 'd_client'] = 'ca-p' + 'ub-6974184241884155';
        superSpecialObject['enable_page_level_a' + 'ds'] = true;
       (window['a' + 'dsbygoogle'] = window['a' + 'dsbygoogle'] || []).push(superSpecialObject);
  </script>
</head>

<body>
  <!--[if lte IE 9]>
    <p class="browserupgrade">You are using an <strong>outdated</strong> browser. Please <a href="https://browsehappy.com/">upgrade your browser</a> to improve your experience and security.</p>
  <![endif]-->
  <header class="page-header js-page-header">
    <a class="page-header-logo-container" href="https://weekly-geekly-es.github.io/index.html"></a>
    <div class="page-header-text">Geekly articles weekly</div>
  </header>
  <section class="page js-page"><h1>Excepciones devastadoras</h1><div class="post__body post__body_full"><div class="post__text post__text-html post__text_v1" id="post-content-body" data-io-article-url="https://habr.com/ru/post/433944/"><h2 id="eschyo-raz-o-tom-pochemu-ploho-brosat-isklyucheniya-v-destruktorah">  Una vez m√°s sobre por qu√© es malo lanzar excepciones en destructores </h2><br><p>  Muchos expertos en C ++ (por ejemplo, <a href="https://translate.googleusercontent.com/translate_c?depth=1&amp;rurl=translate.google.com&amp;sl=ru&amp;sp=nmt4&amp;tl=es&amp;u=">Herb Sutter</a> ) nos ense√±an que lanzar excepciones en los destructores es malo, porque puedes ingresar al destructor durante la promoci√≥n de la pila cuando ya se lanza una excepci√≥n, y si en ese momento se lanza otra excepci√≥n, se llamar√° <em>std</em> como resultado <em>:: terminar ()</em> .  El est√°ndar de lenguaje C ++ 17 (en adelante me refiero a la versi√≥n disponible gratuitamente del borrador <a href="https://translate.googleusercontent.com/translate_c?depth=1&amp;rurl=translate.google.com&amp;sl=ru&amp;sp=nmt4&amp;tl=es&amp;u=">N4713</a> ) sobre este tema nos dice lo siguiente: </p><a name="habracut"></a><br><blockquote>  <strong>18.5.1 La funci√≥n std :: terminate () [excepto.terminate]</strong> <br><br>  1 En algunas situaciones, se debe abandonar el manejo de excepciones para t√©cnicas de manejo de errores menos sutiles.  [Nota: <br><br>  Estas situaciones son: <br><br>  ... <br><br>  (1.4) cuando la destrucci√≥n de un objeto durante el desbobinado de la pila (18.2) termina lanzando una excepci√≥n, o <br><br>  ... <br><br>  - nota final] </blockquote><p>  Veamos un ejemplo simple: </p><br><pre><code class="plaintext hljs">#include &lt;iostream&gt; class PrintInDestructor { public: ~PrintInDestructor() noexcept { std::cerr &lt;&lt; "~PrintInDestructor() invoked\n"; } }; void throw_int_func() { std::cerr &lt;&lt; "throw_int_func() invoked\n"; throw 1; } class ThrowInDestructor { public: ~ThrowInDestructor() noexcept(false) { std::cerr &lt;&lt; "~ThrowInDestructor() invoked\n"; throw_int_func(); } private: PrintInDestructor member_; }; int main(int, char**) { try { ThrowInDestructor bad; throw "BANG!"; } catch (int i) { std::cerr &lt;&lt; "Catched int exception: " &lt;&lt; i &lt;&lt; "\n"; } catch (const char* c) { std::cerr &lt;&lt; "Catched const char* exception: " &lt;&lt; c &lt;&lt; "\n"; } catch (...) { std::cerr &lt;&lt; "Catched unknown exception\n"; } return 0; }</code> </pre> <br><p>  Resultado: </p><br><pre> <code class="plaintext hljs">~ThrowInDestructor() invoked throw_int_func() invoked ~PrintInDestructor() invoked terminate called after throwing an instance of 'int' Aborted</code> </pre> <br><p>  Tenga en cuenta que todav√≠a se llama al destructor <em>PrintInDestructor</em> , es decir  despu√©s de lanzar la segunda excepci√≥n, la promoci√≥n de la pila no se interrumpe.  La Norma (el mismo p√°rrafo 18.5.1) sobre este tema dice lo siguiente: </p><br><blockquote>  2 ... En la situaci√≥n en la que no se encuentra un controlador coincidente, <br>  est√° definido por la implementaci√≥n si la pila se desenrolla o no antes de llamar a std :: terminate ().  En <br>  la situaci√≥n en la que la b√∫squeda de un controlador (18.3) encuentra el bloque m√°s externo de una funci√≥n con un <br>  especificaci√≥n de excepci√≥n de no lanzamiento (18.4), est√° definida por la implementaci√≥n si la pila est√° desenrollada, <br>  desenrollado parcialmente, o no desenrollado antes de que se llame a std :: terminate () ... </blockquote><p>  Prob√© este ejemplo en varias versiones de <strong>GCC</strong> (8.2, 7.3) y <strong>Clang</strong> (6.0, 5.0), en todas partes contin√∫a la promoci√≥n de la pila.  Si se encuentra con un compilador donde la implementaci√≥n definida es diferente, escr√≠bala en los comentarios. </p><br><p>  Tambi√©n debe tenerse en cuenta que <em>std :: terminate ()</em> se llama cuando la pila se desenrolla solo cuando se arroja una excepci√≥n del destructor.  Si hay un bloque try / catch dentro del destructor que captura la excepci√≥n y no lanza m√°s, esto no interrumpe la promoci√≥n de la pila de la excepci√≥n externa. </p><br><pre> <code class="plaintext hljs">class ThrowCatchInDestructor { public: ~ThrowCatchInDestructor() noexcept(false) { try { throw_int_func(); } catch (int i) { std::cerr &lt;&lt; "Catched int in ~ThrowCatchInDestructor(): " &lt;&lt; i &lt;&lt; "\n"; } } private: PrintInDestructor member_; }; int main(int, char**) { try { ThrowCatchInDestructor good; std::cerr &lt;&lt; "ThrowCatchInDestructor instance created\n"; throw "BANG!"; } catch (int i) { std::cerr &lt;&lt; "Catched int exception: " &lt;&lt; i &lt;&lt; "\n"; } catch (const char* s) { std::cerr &lt;&lt; "Catched const char* exception: " &lt;&lt; s &lt;&lt; "\n"; } catch (...) { std::cerr &lt;&lt; "Catched unknown exception\n"; } return 0; }</code> </pre> <br><p>  muestra </p><br><pre> <code class="plaintext hljs">ThrowCatchInDestructor instance created throw_int_func() invoked Catched int in ~ThrowCatchInDestructor(): 1 ~PrintInDestructor() invoked Catched const char* exception: BANG!</code> </pre> <br><p>  ¬øC√≥mo evitar situaciones desagradables?  En teor√≠a, todo es simple: nunca arroje excepciones en el destructor.  Sin embargo, en la pr√°ctica, no es tan simple darse cuenta de este requisito tan simple y elegante. </p><br><h2 id="esli-nelzya-no-ochen-hochetsya">  Si no puedes, pero realmente quieres ... </h2><br><blockquote>  Notar√© de inmediato que no estoy tratando de justificar el lanzamiento de excepciones desde el destructor, y siguiendo a Sutter, Meyers y otros gur√∫s de C ++, les insto <strong>a que</strong> nunca <strong>intenten</strong> hacer esto (al menos en el nuevo c√≥digo).  Sin embargo, en la pr√°ctica real, un programador puede encontrar c√≥digo heredado, que no es tan f√°cil de llevar a altos est√°ndares.  Adem√°s, las t√©cnicas que a menudo se describen a continuaci√≥n pueden ser √∫tiles en el proceso de depuraci√≥n. </blockquote><p>  Por ejemplo, estamos desarrollando una biblioteca con una clase contenedora que encapsula el trabajo con un determinado recurso.  De acuerdo con los principios de RAII, tomamos el recurso en el constructor y debemos liberarlo en el destructor.  Pero, ¬øqu√© pasa si falla un intento de liberar un recurso?  Opciones para resolver este problema: </p><br><ul><li>  Ignora el error.  Malo, porque estamos ocultando un problema que podr√≠a afectar otras partes del sistema. </li><li>  Escribe en el registro.  Mejor que simplemente ignorarlo, pero sigue siendo malo, porque  nuestra biblioteca no sabe nada acerca de las pol√≠ticas de registro adoptadas en el sistema que lo utiliza.  El registro est√°ndar se puede redirigir a / dev / null, como resultado de lo cual, nuevamente, no veremos un error. </li><li>  Tome la liberaci√≥n del recurso en una funci√≥n separada que devuelva un valor o arroje una excepci√≥n, y obligue al usuario de la clase a llamarlo por su cuenta.  Es malo, porque el usuario puede olvidarse de hacer esto y recibiremos una fuga de recursos. </li><li>  Lanza una excepci√≥n.  Bueno en casos ordinarios, como  el usuario de la clase puede detectar la excepci√≥n y obtener informaci√≥n sobre el error de la manera est√°ndar.  Mal durante la promoci√≥n de la pila, como  conduce a <em>std :: terminate ()</em> . </li></ul><br><p>  ¬øC√≥mo entender si actualmente estamos en el proceso de promover la pila por excepci√≥n o no?  En C ++, hay una funci√≥n especial <em>std :: uncaught_exception () para esto</em> .  Con su ayuda, podemos lanzar de manera segura una excepci√≥n en una situaci√≥n normal, o hacer algo menos correcto, pero sin generar una excepci√≥n durante la promoci√≥n de la pila. </p><br><pre> <code class="plaintext hljs">class ThrowInDestructor { public: ~ThrowInDestructor() noexcept(false) { if (std::uncaught_exception()) { std::cerr &lt;&lt; "~ThrowInDestructor() stack unwinding, not throwing\n"; } else { std::cerr &lt;&lt; "~ThrowInDestructor() normal case, throwing\n"; throw_int_func(); } } private: PrintInDestructor member_; }; int main(int, char**) { try { ThrowInDestructor normal; std::cerr &lt;&lt; "ThrowInDestructor normal destruction\n"; } catch (int i) { std::cerr &lt;&lt; "Catched int exception: " &lt;&lt; i &lt;&lt; "\n"; } try { ThrowInDestructor stack_unwind; std::cerr &lt;&lt; "ThrowInDestructor stack unwinding\n"; throw "BANG!"; } catch (int i) { std::cerr &lt;&lt; "Catched int exception: " &lt;&lt; i &lt;&lt; "\n"; } catch (const char* s) { std::cerr &lt;&lt; "Catched const char* exception: " &lt;&lt; s &lt;&lt; "\n"; } catch (...) { std::cerr &lt;&lt; "Catched unknown exception\n"; } return 0; }</code> </pre> <br><p>  Resultado: </p><br><pre> <code class="plaintext hljs">ThrowInDestructor normal destruction ~ThrowInDestructor() normal case, throwing throw_int_func() invoked ~PrintInDestructor() invoked Catched int exception: 1 ThrowInDestructor stack unwinding ~ThrowInDestructor() stack unwinding, not throwing ~PrintInDestructor() invoked Catched const char* exception: BANG!</code> </pre> <br><p>  Tenga en cuenta que la funci√≥n <em>std :: uncaught_exception ()</em> est√° en <em>desuso</em> desde C ++ Standard 17, por lo tanto, para compilar el ejemplo, se debe suprimir el vorning correspondiente (consulte el <a href="https://translate.googleusercontent.com/translate_c?depth=1&amp;rurl=translate.google.com&amp;sl=ru&amp;sp=nmt4&amp;tl=es&amp;u=">repositorio con ejemplos del art√≠culo</a> ). </p><br><p>  El problema con esta funci√≥n es que verifica si estamos en el proceso de hacer girar la pila por excepci√≥n.  Pero es imposible entender si se llama al destructor actual durante el proceso de promoci√≥n de la pila.  Como resultado, si hay una promoci√≥n de pila, pero el destructor de alg√∫n objeto se llama normalmente, <em>std :: uncaught_exception ()</em> a√∫n devolver√° <em>verdadero</em> . </p><br><pre> <code class="plaintext hljs">class MayThrowInDestructor { public: ~MayThrowInDestructor() noexcept(false) { if (std::uncaught_exception()) { std::cerr &lt;&lt; "~MayThrowInDestructor() stack unwinding, not throwing\n"; } else { std::cerr &lt;&lt; "~MayThrowInDestructor() normal case, throwing\n"; throw_int_func(); } } }; class ThrowCatchInDestructor { public: ~ThrowCatchInDestructor() noexcept(false) { try { MayThrowInDestructor may_throw; } catch (int i) { std::cerr &lt;&lt; "Catched int in ~ThrowCatchInDestructor(): " &lt;&lt; i &lt;&lt; "\n"; } } private: PrintInDestructor member_; }; int main(int, char**) { try { ThrowCatchInDestructor stack_unwind; std::cerr &lt;&lt; "ThrowInDestructor stack unwinding\n"; throw "BANG!"; } catch (int i) { std::cerr &lt;&lt; "Catched int exception: " &lt;&lt; i &lt;&lt; "\n"; } catch (const char* s) { std::cerr &lt;&lt; "Catched const char* exception: " &lt;&lt; s &lt;&lt; "\n"; } catch (...) { std::cerr &lt;&lt; "Catched unknown exception\n"; } return 0; }</code> </pre> <br><p>  Resultado: </p><br><pre> <code class="plaintext hljs">ThrowInDestructor stack unwinding ~MayThrowInDestructor() stack unwinding, not throwing ~PrintInDestructor() invoked Catched const char* exception: BANG!</code> </pre> <br><p>  En el nuevo est√°ndar C ++ 17, la funci√≥n <em>std :: uncaught_exceptions ()</em> se introdujo para reemplazar <em>std :: uncaught_exception ()</em> (tenga en cuenta el plural), que en lugar de un valor booleano devuelve el n√∫mero de excepciones actualmente activas (aqu√≠ hay una <a href="https://translate.googleusercontent.com/translate_c?depth=1&amp;rurl=translate.google.com&amp;sl=ru&amp;sp=nmt4&amp;tl=es&amp;u=">justificaci√≥n</a> detallada). </p><br><p>  As√≠ es como se resuelve el problema descrito anteriormente con <em>std :: uncaught_exceptions ()</em> : </p><br><pre> <code class="plaintext hljs">class MayThrowInDestructor { public: MayThrowInDestructor() : exceptions_(std::uncaught_exceptions()) {} ~MayThrowInDestructor() noexcept(false) { if (std::uncaught_exceptions() &gt; exceptions_) { std::cerr &lt;&lt; "~MayThrowInDestructor() stack unwinding, not throwing\n"; } else { std::cerr &lt;&lt; "~MayThrowInDestructor() normal case, throwing\n"; throw_int_func(); } } private: int exceptions_; }; class ThrowCatchInDestructor { public: ~ThrowCatchInDestructor() noexcept(false) { try { MayThrowInDestructor may_throw; } catch (int i) { std::cerr &lt;&lt; "Catched int in ~ThrowCatchInDestructor(): " &lt;&lt; i &lt;&lt; "\n"; } } private: PrintInDestructor member_; }; int main(int, char**) { try { ThrowCatchInDestructor stack_unwind; std::cerr &lt;&lt; "ThrowInDestructor stack unwinding\n"; throw "BANG!"; } catch (int i) { std::cerr &lt;&lt; "Catched int exception: " &lt;&lt; i &lt;&lt; "\n"; } catch (const char* s) { std::cerr &lt;&lt; "Catched const char* exception: " &lt;&lt; s &lt;&lt; "\n"; } catch (...) { std::cerr &lt;&lt; "Catched unknown exception\n"; } return 0; }</code> </pre> <br><p>  Resultado: </p><br><pre> <code class="plaintext hljs">ThrowInDestructor stack unwinding ~MayThrowInDestructor() normal case, throwing throw_int_func() invoked Catched int in ~ThrowCatchInDestructor(): 1 ~PrintInDestructor() invoked Catched const char* exception: BANG!</code> </pre> <br><h2 id="kogda-ochen-ochen-hochetsya-vybrosit-srazu-neskolko-isklyucheniy">  Cuando realmente quiero lanzar algunas excepciones a la vez </h2><br><p>  <em>std :: uncaught_exceptions ()</em> evita llamar a <em>std :: terminate ()</em> , pero no ayuda a manejar varias excepciones correctamente.  Idealmente, me gustar√≠a tener un mecanismo que me permitiera guardar todas las excepciones lanzadas y luego procesarlas en un solo lugar. </p><br><blockquote>  Quiero recordar una vez m√°s que el mecanismo propuesto por m√≠ a continuaci√≥n solo sirve para demostrar el concepto y no se recomienda su uso en el c√≥digo industrial real. </blockquote><p>  La esencia de la idea es capturar excepciones y guardarlas en un contenedor, y luego obtenerlas y procesarlas una por una.  Para guardar objetos de excepci√≥n, C ++ tiene un tipo especial <em>std :: exception_ptr</em> .  La estructura de tipo en el Est√°ndar no se revela, pero se dice que es esencialmente <em>shared_ptr</em> por objeto de excepci√≥n. </p><br><p>  ¬øC√≥mo, entonces, procesar estas excepciones?  Hay una funci√≥n <em>std :: rethrow_exception () para esto</em> , que toma un puntero <em>std :: exception_ptr</em> y lanza la excepci√≥n correspondiente.  Solo necesitamos atraparlo con la secci√≥n de captura correspondiente y procesarlo, despu√©s de lo cual podemos pasar al siguiente objeto de excepci√≥n. </p><br><pre> <code class="plaintext hljs">using exceptions_queue = std::stack&lt;std::exception_ptr&gt;; // Get exceptions queue for current thread exceptions_queue&amp; get_queue() { thread_local exceptions_queue queue_; return queue_; } // Invoke functor and save exception in queue void safe_invoke(std::function&lt;void()&gt; f) noexcept { try { f(); } catch (...) { get_queue().push(std::current_exception()); } } class ThrowInDestructor { public: ~ThrowInDestructor() noexcept { std::cerr &lt;&lt; "~ThrowInDestructor() invoked\n"; safe_invoke([]() { throw_int_func(); }); } private: PrintInDestructor member_; }; int main(int, char**) { safe_invoke([]() { ThrowInDestructor bad; throw "BANG!"; }); auto&amp; q = get_queue(); while (!q.empty()) { try { std::exception_ptr ex = q.top(); q.pop(); if (ex != nullptr) { std::rethrow_exception(ex); } } catch (int i) { std::cerr &lt;&lt; "Catched int exception: " &lt;&lt; i &lt;&lt; "\n"; } catch (const char* s) { std::cerr &lt;&lt; "Catched const char* exception: " &lt;&lt; s &lt;&lt; "\n"; } catch (...) { std::cerr &lt;&lt; "Catched unknown exception\n"; } } return 0; }</code> </pre> <br><p>  Resultado: </p><br><pre> <code class="plaintext hljs">~ThrowInDestructor() invoked throw_int_func() invoked ~PrintInDestructor() invoked Catched const char* exception: BANG! Catched int exception: 1</code> </pre> <br><p>  En el ejemplo anterior, la pila se usa para guardar objetos de excepci√≥n, sin embargo, el manejo de excepciones se realizar√° de acuerdo con el principio FIFO (es decir, l√≥gicamente esta es la cola; la excepci√≥n lanzada por el primero se procesar√° primero). </p><br><h2 id="vyvody">  Conclusiones </h2><br><p>  Lanzar excepciones en los destructores de objetos es realmente una mala idea, y en cualquier c√≥digo nuevo, recomiendo encarecidamente no hacerlo declarando destructores <em>noexcept</em> .  Sin embargo, con el soporte y la depuraci√≥n del c√≥digo heredado, puede ser necesario manejar correctamente las excepciones generadas por los destructores, incluso durante la promoci√≥n de la pila, y C ++ moderno nos proporciona mecanismos para esto.  Espero que las ideas presentadas en el art√≠culo te ayuden en este dif√≠cil camino. </p><br><h2 id="ssylki">  Referencias </h2><br><p>  <a href="https://translate.googleusercontent.com/translate_c?depth=1&amp;rurl=translate.google.com&amp;sl=ru&amp;sp=nmt4&amp;tl=es&amp;u=">Repositorio con ejemplos del art√≠culo.</a> </p></div></div><p>Source: <a rel="nofollow" href="https://habr.com/ru/post/es433944/">https://habr.com/ru/post/es433944/</a></p>
<section class="more-articles-navigation-panel js-more-articles-navigation-panel">
<h4>More articles:</h4>
<nav class="list-of-articles-container js-list-of-articles-container"><ul class="list-of-pages js-list-of-pages">
<li><a href="../es433932/index.html">Disparamos en el pie, procesando los datos de entrada.</a></li>
<li><a href="../es433934/index.html">Marco √°gil SAFe o escalado</a></li>
<li><a href="../es433936/index.html">¬øBusca un regalo de alta tecnolog√≠a para un ni√±o? Piensa en un patio de recreo, no en un corralito</a></li>
<li><a href="../es433938/index.html">C√≥mo Yandex y Google resumen el a√±o</a></li>
<li><a href="../es433940/index.html">¬øCu√°nto cuesta la revisi√≥n en la AppStore?</a></li>
<li><a href="../es433946/index.html">Hoja de trucos para la inteligencia artificial: deseche el exceso, ense√±e lo principal. T√©cnica de procesamiento de secuencia de entrenamiento</a></li>
<li><a href="../es433948/index.html">C√≥mo hacer que el pago sea m√°s conveniente: la experiencia de un proveedor de IaaS</a></li>
<li><a href="../es433952/index.html">10 razones para elegir una soluci√≥n para SAP HANA de HPE. Parte 2</a></li>
<li><a href="../es433954/index.html">Ocho tecnolog√≠as de audio y dispositivos de audio que ingresar√°n al Sal√≥n de la Fama de TECnology en 2019</a></li>
<li><a href="../es433956/index.html">Los modders han usado IA para mejorar la textura en los juegos.</a></li>
</ul></nav>
</section><br />
<a href="../../allArticles.html"><strong>All Articles</strong></a>
<script src="../../js/main.js"></script>

<!-- Yandex.Metrika counter -->
<script type="text/javascript" >
  (function (d, w, c) {
      (w[c] = w[c] || []).push(function() {
          try {
              w.yaCounter57283870 = new Ya.Metrika({
                  id:57283870,
                  clickmap:true,
                  trackLinks:true,
                  accurateTrackBounce:true,
                  webvisor:true
              });
          } catch(e) { }
      });

      var n = d.getElementsByTagName("script")[0],
          s = d.createElement("script"),
          f = function () { n.parentNode.insertBefore(s, n); };
      s.type = "text/javascript";
      s.async = true;
      s.src = "https://mc.yandex.ru/metrika/watch.js";

      if (w.opera == "[object Opera]") {
          d.addEventListener("DOMContentLoaded", f, false);
      } else { f(); }
  })(document, window, "yandex_metrika_callbacks");
</script>
<noscript><div><img src="https://mc.yandex.ru/watch/57283870" style="position:absolute; left:-9999px;" alt="" /></div></noscript>

<!-- Google Analytics -->
  <script>
    window.ga = function () { ga.q.push(arguments) }; ga.q = []; ga.l = +new Date;
    ga('create', 'UA-134228602-6', 'auto'); ga('send', 'pageview')
  </script>
  <script src="https://www.google-analytics.com/analytics.js" async defer></script>

</section>

<footer class="page-footer">
  <div class="page-footer-legal-info-container page-footer-element">
    <p>
      Weekly-Geekly ES | <span class="page-footer-legal-info-year js-page-footer-legal-info-year">2019</span>
    </p>
  </div>
  <div class="page-footer-counters-container page-footer-element">
    <a class="page-footer-counter-clustrmap" href='#'  title='Visit tracker'><img src='https://clustrmaps.com/map_v2.png?cl=698e5a&w=271&t=t&d=9uU9J9pq8z7k8xEBHYSfs6DenIBAHs3vLIHcPIJW9d0&co=3a3a3a&ct=ffffff'/></a>
  </div>
</footer>
  
</body>

</html>